Workbook

Sheet experimental material design 
A1: No. | B1: Activation Material | C1: Activation Reaction | D1: Activation Product | E1: Half-life of Activation Product (hr) | F1: Cross-section Database | G1: ASTM | H1: Mass (g) | I1: Atomic Weight | J1: Irradiation Time (hr) | K1: Cooling Time (hr)
A2: 1 | B2: Au-197 | C2: (n,r) | D2: Au-198 | E2: =2.69*24 -> 64.56 | F2: ENDF/B-VIII.1 | G2: E720-16 | H2: 1 | I2: 197 | J2: 6 | K2: 6
A3: 2 | B3: Fe-56 | C3: (n,p) | D3: Mn-56 | E3: 2.57878 | F3: ENDF/B-VIII.0 | G3: E720-16 | H3: 1 | I3: 56 | J3: 6 | K3: 6
A4: 3 | B4: Al-27 | C4: (n,a) | D4: Na-24 | E4: 15 | F4: IRDF-2002G | G4: E266-92 | H4: 1 | I4: 27 | J4: 6 | K4: 6
A5: 4 | B5: Ni-58 | C5: (n,p) | D5: Co-58 | E5: =70.85*24 -> 1700.4 | F5: ENDF/B-VI | G5: E264-19 | H5: 5 | I5: 58 | J5: 6 | K5: 6
A6: 5 | B6: Fe-54 | C6: (n,p) | D6: Mn-54 | E6: =312.19*24 -> 7492.56 | F6: ENDF/B-VIII.1 | G6: E263-18 | H6: 5 | I6: 54 | J6: 6 | K6: 6
A7: 6 | B7: Cu-63 | C7: (n,a) | D7: Co-60 | E7: =5.2711*365*24 -> 46174.836 | F7: ENDF/B-VI | G7: E523-92 | H7: 50 | I7: 63 | J7: 6 | K7: 6
A8: 7 | B8: Ti-48 | C8: (n,p) | D8: Sc-48 | E8: =83.81*24 -> 2011.44 | F8: EAF-2010 | G8: E526-92 | H8: 50 | I8: 48 | J8: 6 | K8: 6
A9: 8 | B9: Na-23 | C9: (n,r) | D9: Na-24 | E9: 14.4958 | F9: ENDF/B-VIII.1 | G9: E720-16 | H9: 1 | I9: 23 | J9: 6 | K9: 6
A10: 9 | B10: Co-59 | C10: (n,r) | D10: Co-60 | E10: =5.2711*365*24 -> 46174.836 | F10: ENDF/B-VIII.1 | G10: E720-16 | H10: 1 | I10: 59 | J10: 6 | K10: 6
A11: 10 | B11: S-32 | C11: (n,p) | D11: P-32 | E11: =14.284*24 -> 342.816 | F11: ENDF/B-VIII.1 | G11: E720-16 | H11: 1 | I11: 32 | J11: 6 | K11: 6

Sheet activity_Ami
A1: Au-197 | F1: Fe-56 | K1: Al-27 | P1: Ni-58 | U1: Fe-54 | Z1: Cu-63 | AE1: Ti-48 | AJ1: Na-23 | AO1: Co-59 | AT1: S-32
A2: Energy | B2: Flux(ground truth) | C2: Coefficient | D2: Activity | F2: Energy | G2: Flux(ground truth) | H2: Coefficient | I2: Activity | K2: Energy | L2: Flux(ground truth) | M2: Coefficient | N2: Activity | P2: Energy | Q2: Flux(ground truth) | R2: Coefficient | S2: Activity | U2: Energy | V2: Flux(ground truth) | W2: Coefficient | X2: Activity | Z2: Energy | AA2: Flux(ground truth) | AB2: Coefficient | AC2: Activity | AE2: Energy | AF2: Flux(ground truth) | AG2: Coefficient | AH2: Activity | AJ2: Energy | AK2: Flux(ground truth) | AL2: Coefficient | AM2: Activity | AO2: Energy | AP2: Flux(ground truth) | AQ2: Coefficient | AR2: Activity | AT2: Energy | AU2: Flux(ground truth) | AV2: Coefficient | AW2: Activity
A3: 1e-11 | B3: 0 | C3: 0 | D3: =B3*C3 -> 0 | F3: 1e-11 | G3: 0 | H3: 0 | I3: =G3*H3 -> 0 | K3: 1e-11 | L3: 0 | M3: 0 | N3: =L3*M3 -> 0 | P3: 1e-11 | Q3: 0 | R3: 0 | S3: =Q3*R3 -> 0 | U3: 1e-11 | V3: 0 | W3: 0 | X3: =V3*W3 -> 0 | Z3: 1e-11 | AA3: 0 | AB3: 0 | AC3: =AA3*AB3 -> 0 | AE3: 1e-11 | AF3: 0 | AG3: 0 | AH3: =AF3*AG3 -> 0 | AJ3: 1e-11 | AK3: 0 | AL3: 0 | AM3: =AK3*AL3 -> 0 | AO3: 1e-11 | AP3: 0 | AQ3: 0 | AR3: =AP3*AQ3 -> 0 | AT3: 1e-11 | AU3: 0 | AV3: 0 | AW3: =AU3*AV3 -> 0
A4: 1.1286e-11 | B4: 0 | C4: 0.8581143 | D4: =B4*C4 -> 0 | F4: 1.1286e-11 | G4: 0 | H4: 0 | I4: =G4*H4 -> 0 | K4: 1.1286e-11 | L4: 0 | M4: 0 | N4: =L4*M4 -> 0 | P4: 1.1286e-11 | Q4: 0 | R4: 0 | S4: =Q4*R4 -> 0 | U4: 1.1286e-11 | V4: 0 | W4: 0 | X4: =V4*W4 -> 0 | Z4: 1.1286e-11 | AA4: 0 | AB4: 0 | AC4: =AA4*AB4 -> 0 | AE4: 1.1286e-11 | AF4: 0 | AG4: 0 | AH4: =AF4*AG4 -> 0 | AJ4: 1.1286e-11 | AK4: 0 | AL4: 0.12705359 | AM4: =AK4*AL4 -> 0 | AO4: 1.1286e-11 | AP4: 0 | AQ4: 0.0016766268 | AR4: =AP4*AQ4 -> 0 | AT4: 1.1286e-11 | AU4: 0 | AV4: 0 | AW4: =AU4*AV4 -> 0
A5: 1.2738e-11 | B5: 0 | C5: 0.79702672 | D5: =B5*C5 -> 0 | F5: 1.2738e-11 | G5: 0 | H5: 0 | I5: =G5*H5 -> 0 | K5: 1.2738e-11 | L5: 0 | M5: 0 | N5: =L5*M5 -> 0 | P5: 1.2738e-11 | Q5: 0 | R5: 0 | S5: =Q5*R5 -> 0 | U5: 1.2738e-11 | V5: 0 | W5: 0 | X5: =V5*W5 -> 0 | Z5: 1.2738e-11 | AA5: 0 | AB5: 0 | AC5: =AA5*AB5 -> 0 | AE5: 1.2738e-11 | AF5: 0 | AG5: 0 | AH5: =AF5*AG5 -> 0 | AJ5: 1.2738e-11 | AK5: 0 | AL5: 0.1180086 | AM5: =AK5*AL5 -> 0 | AO5: 1.2738e-11 | AP5: 0 | AQ5: 0.0015572688 | AR5: =AP5*AQ5 -> 0 | AT5: 1.2738e-11 | AU5: 0 | AV5: 0 | AW5: =AU5*AV5 -> 0
A6: 1.4376e-11 | B6: 0 | C6: 0.75888799 | D6: =B6*C6 -> 0 | F6: 1.4376e-11 | G6: 0 | H6: 0 | I6: =G6*H6 -> 0 | K6: 1.4376e-11 | L6: 0 | M6: 0 | N6: =L6*M6 -> 0 | P6: 1.4376e-11 | Q6: 0 | R6: 0 | S6: =Q6*R6 -> 0 | U6: 1.4376e-11 | V6: 0 | W6: 0 | X6: =V6*W6 -> 0 | Z6: 1.4376e-11 | AA6: 0 | AB6: 0 | AC6: =AA6*AB6 -> 0 | AE6: 1.4376e-11 | AF6: 0 | AG6: 0 | AH6: =AF6*AG6 -> 0 | AJ6: 1.4376e-11 | AK6: 0 | AL6: 0.11236169 | AM6: =AK6*AL6 -> 0 | AO6: 1.4376e-11 | AP6: 0 | AQ6: 0.0014827482 | AR6: =AP6*AQ6 -> 0 | AT6: 1.4376e-11 | AU6: 0 | AV6: 0 | AW6: =AU6*AV6 -> 0
A7: 1.6225e-11 | B7: 0 | C7: 0.72257458 | D7: =B7*C7 -> 0 | F7: 1.6225e-11 | G7: 0 | H7: 0 | I7: =G7*H7 -> 0 | K7: 1.6225e-11 | L7: 0 | M7: 0 | N7: =L7*M7 -> 0 | P7: 1.6225e-11 | Q7: 0 | R7: 0 | S7: =Q7*R7 -> 0 | U7: 1.6225e-11 | V7: 0 | W7: 0 | X7: =V7*W7 -> 0 | Z7: 1.6225e-11 | AA7: 0 | AB7: 0 | AC7: =AA7*AB7 -> 0 | AE7: 1.6225e-11 | AF7: 0 | AG7: 0 | AH7: =AF7*AG7 -> 0 | AJ7: 1.6225e-11 | AK7: 0 | AL7: 0.10698532 | AM7: =AK7*AL7 -> 0 | AO7: 1.6225e-11 | AP7: 0 | AQ7: 0.0014118024 | AR7: =AP7*AQ7 -> 0 | AT7: 1.6225e-11 | AU7: 0 | AV7: 0 | AW7: =AU7*AV7 -> 0
A8: 1.8313e-11 | B8: 0 | C8: 0.6715388 | D8: =B8*C8 -> 0 | F8: 1.8313e-11 | G8: 0 | H8: 0 | I8: =G8*H8 -> 0 | K8: 1.8313e-11 | L8: 0 | M8: 0 | N8: =L8*M8 -> 0 | P8: 1.8313e-11 | Q8: 0 | R8: 0 | S8: =Q8*R8 -> 0 | U8: 1.8313e-11 | V8: 0 | W8: 0 | X8: =V8*W8 -> 0 | Z8: 1.8313e-11 | AA8: 0 | AB8: 0 | AC8: =AA8*AB8 -> 0 | AE8: 1.8313e-11 | AF8: 0 | AG8: 0 | AH8: =AF8*AG8 -> 0 | AJ8: 1.8313e-11 | AK8: 0 | AL8: 0.099428513 | AM8: =AK8*AL8 -> 0 | AO8: 1.8313e-11 | AP8: 0 | AQ8: 0.0013120832 | AR8: =AP8*AQ8 -> 0 | AT8: 1.8313e-11 | AU8: 0 | AV8: 0 | AW8: =AU8*AV8 -> 0
A9: 2.0668e-11 | B9: 0 | C9: 0.62373354 | D9: =B9*C9 -> 0 | F9: 2.0668e-11 | G9: 0 | H9: 0 | I9: =G9*H9 -> 0 | K9: 2.0668e-11 | L9: 0 | M9: 0 | N9: =L9*M9 -> 0 | P9: 2.0668e-11 | Q9: 0 | R9: 0 | S9: =Q9*R9 -> 0 | U9: 2.0668e-11 | V9: 0 | W9: 0 | X9: =V9*W9 -> 0 | Z9: 2.0668e-11 | AA9: 0 | AB9: 0 | AC9: =AA9*AB9 -> 0 | AE9: 2.0668e-11 | AF9: 0 | AG9: 0 | AH9: =AF9*AG9 -> 0 | AJ9: 2.0668e-11 | AK9: 0 | AL9: 0.092350036 | AM9: =AK9*AL9 -> 0 | AO9: 2.0668e-11 | AP9: 0 | AQ9: 0.0012186774 | AR9: =AP9*AQ9 -> 0 | AT9: 2.0668e-11 | AU9: 0 | AV9: 0 | AW9: =AU9*AV9 -> 0
A10: 2.3326e-11 | B10: 0 | C10: 0.59388654 | D10: =B10*C10 -> 0 | F10: 2.3326e-11 | G10: 0 | H10: 0 | I10: =G10*H10 -> 0 | K10: 2.3326e-11 | L10: 0 | M10: 0 | N10: =L10*M10 -> 0 | P10: 2.3326e-11 | Q10: 0 | R10: 0 | S10: =Q10*R10 -> 0 | U10: 2.3326e-11 | V10: 0 | W10: 0 | X10: =V10*W10 -> 0 | Z10: 2.3326e-11 | AA10: 0 | AB10: 0 | AC10: =AA10*AB10 -> 0 | AE10: 2.3326e-11 | AF10: 0 | AG10: 0 | AH10: =AF10*AG10 -> 0 | AJ10: 2.3326e-11 | AK10: 0 | AL10: 0.087931317 | AM10: =AK10*AL10 -> 0 | AO10: 2.3326e-11 | AP10: 0 | AQ10: 0.0011603585 | AR10: =AP10*AQ10 -> 0 | AT10: 2.3326e-11 | AU10: 0 | AV10: 0 | AW10: =AU10*AV10 -> 0
A11: 2.6327e-11 | B11: 0 | C11: 0.56546976 | D11: =B11*C11 -> 0 | F11: 2.6327e-11 | G11: 0 | H11: 0 | I11: =G11*H11 -> 0 | K11: 2.6327e-11 | L11: 0 | M11: 0 | N11: =L11*M11 -> 0 | P11: 2.6327e-11 | Q11: 0 | R11: 0 | S11: =Q11*R11 -> 0 | U11: 2.6327e-11 | V11: 0 | W11: 0 | X11: =V11*W11 -> 0 | Z11: 2.6327e-11 | AA11: 0 | AB11: 0 | AC11: =AA11*AB11 -> 0 | AE11: 2.6327e-11 | AF11: 0 | AG11: 0 | AH11: =AF11*AG11 -> 0 | AJ11: 2.6327e-11 | AK11: 0 | AL11: 0.083723831 | AM11: =AK11*AL11 -> 0 | AO11: 2.6327e-11 | AP11: 0 | AQ11: 0.0011048333 | AR11: =AP11*AQ11 -> 0 | AT11: 2.6327e-11 | AU11: 0 | AV11: 0 | AW11: =AU11*AV11 -> 0
A12: 2.9713e-11 | B12: 0 | C12: 0.52552984 | D12: =B12*C12 -> 0 | F12: 2.9713e-11 | G12: 0 | H12: 0 | I12: =G12*H12 -> 0 | K12: 2.9713e-11 | L12: 0 | M12: 0 | N12: =L12*M12 -> 0 | P12: 2.9713e-11 | Q12: 0 | R12: 0 | S12: =Q12*R12 -> 0 | U12: 2.9713e-11 | V12: 0 | W12: 0 | X12: =V12*W12 -> 0 | Z12: 2.9713e-11 | AA12: 0 | AB12: 0 | AC12: =AA12*AB12 -> 0 | AE12: 2.9713e-11 | AF12: 0 | AG12: 0 | AH12: =AF12*AG12 -> 0 | AJ12: 2.9713e-11 | AK12: 0 | AL12: 0.077810071 | AM12: =AK12*AL12 -> 0 | AO12: 2.9713e-11 | AP12: 0 | AQ12: 0.0010268022 | AR12: =AP12*AQ12 -> 0 | AT12: 2.9713e-11 | AU12: 0 | AV12: 0 | AW12: =AU12*AV12 -> 0
A13: 3.3535e-11 | B13: 0 | C13: 0.48811784 | D13: =B13*C13 -> 0 | F13: 3.3535e-11 | G13: 0 | H13: 0 | I13: =G13*H13 -> 0 | K13: 3.3535e-11 | L13: 0 | M13: 0 | N13: =L13*M13 -> 0 | P13: 3.3535e-11 | Q13: 0 | R13: 0 | S13: =Q13*R13 -> 0 | U13: 3.3535e-11 | V13: 0 | W13: 0 | X13: =V13*W13 -> 0 | Z13: 3.3535e-11 | AA13: 0 | AB13: 0 | AC13: =AA13*AB13 -> 0 | AE13: 3.3535e-11 | AF13: 0 | AG13: 0 | AH13: =AF13*AG13 -> 0 | AJ13: 3.3535e-11 | AK13: 0 | AL13: 0.072270745 | AM13: =AK13*AL13 -> 0 | AO13: 3.3535e-11 | AP13: 0 | AQ13: 0.00095370596 | AR13: =AP13*AQ13 -> 0 | AT13: 3.3535e-11 | AU13: 0 | AV13: 0 | AW13: =AU13*AV13 -> 0
A14: 3.7848e-11 | B14: 0 | C14: 0.46476227 | D14: =B14*C14 -> 0 | F14: 3.7848e-11 | G14: 0 | H14: 0 | I14: =G14*H14 -> 0 | K14: 3.7848e-11 | L14: 0 | M14: 0 | N14: =L14*M14 -> 0 | P14: 3.7848e-11 | Q14: 0 | R14: 0 | S14: =Q14*R14 -> 0 | U14: 3.7848e-11 | V14: 0 | W14: 0 | X14: =V14*W14 -> 0 | Z14: 3.7848e-11 | AA14: 0 | AB14: 0 | AC14: =AA14*AB14 -> 0 | AE14: 3.7848e-11 | AF14: 0 | AG14: 0 | AH14: =AF14*AG14 -> 0 | AJ14: 3.7848e-11 | AK14: 0 | AL14: 0.068812617 | AM14: =AK14*AL14 -> 0 | AO14: 3.7848e-11 | AP14: 0 | AQ14: 0.00090806725 | AR14: =AP14*AQ14 -> 0 | AT14: 3.7848e-11 | AU14: 0 | AV14: 0 | AW14: =AU14*AV14 -> 0
... A241: 30 | B241: 0 | C241: 0 | D241: =B241*C241 -> 0 | F241: 30 | G241: 0 | H241: 4.1673876e-05 | I241: =G241*H241 -> 0 | K241: 30 | L241: 0 | M241: 0 | N241: =L241*M241 -> 0 | P241: 30 | Q241: 0 | R241: 0 | S241: =Q241*R241 -> 0 | U241: 30 | V241: 0 | W241: 1.3241064e-06 | X241: =V241*W241 -> 0 | Z241: 30 | AA241: 0 | AB241: 0 | AC241: =AA241*AB241 -> 0 | AE241: 30 | AF241: 0 | AG241: 0 | AH241: =AF241*AG241 -> 0 | AJ241: 30 | AK241: 0 | AL241: 0 | AM241: =AK241*AL241 -> 0 | AO241: 30 | AP241: 0 | AQ241: 0 | AR241: =AP241*AQ241 -> 0 | AT241: 30 | AU241: 0 | AV241: 0 | AW241: =AU241*AV241 -> 0
A242: total | B242: =SUM(B3:B241) -> 1605734.6 | D242: =SUM(D3:D241) -> 33834.638 | F242: total | G242: =SUM(G3:G241) -> 1605734.6 | I242: =SUM(I3:I241) -> 14.77296 | K242: total | L242: =SUM(L3:L241) -> 1605734.6 | N242: =SUM(N3:N241) -> 34.918809 | P242: total | Q242: =SUM(Q3:Q241) -> 1605734.6 | S242: =SUM(S3:S241) -> 20.775564 | U242: total | V242: =SUM(V3:V241) -> 1605734.6 | X242: =SUM(X3:X241) -> 4.0947793 | Z242: total | AA242: =SUM(AA3:AA241) -> 1605734.6 | AC242: =SUM(AC3:AC241) -> 0.15076279 | AE242: total | AF242: =SUM(AF3:AF241) -> 1605734.6 | AH242: =SUM(AH3:AH241) -> 4.3623958 | AJ242: total | AK242: =SUM(AK3:AK241) -> 1605734.6 | AM242: =SUM(AM3:AM241) -> 713.15388 | AO242: total | AP242: =SUM(AP3:AP241) -> 1605734.6 | AR242: =SUM(AR3:AR241) -> 10.488252 | AT242: total | AU242: =SUM(AU3:AU241) -> 1605734.6 | AW242: =SUM(AW3:AW241) -> 22.586828

Sheet 60groups_prior
A1: Au-197 | F1: Fe-56 | K1: Al-27 | P1: Ni-58 | U1: Fe-54 | Z1: Cu-63 | AE1: Ti-48 | AJ1: Na-23 | AO1: Co-59 | AT1: S-32
A2: Energy | B2: Flux | C2: Coefficient | D2: Activity | F2: Energy | G2: Flux | H2: Coefficient | I2: Activity | K2: Energy | L2: Flux | M2: Coefficient | N2: Activity | P2: Energy | Q2: Flux | R2: Coefficient | S2: Activity | U2: Energy | V2: Flux | W2: Coefficient | X2: Activity | Z2: Energy | AA2: Flux | AB2: Coefficient | AC2: Activity | AE2: Energy | AF2: Flux | AG2: Coefficient | AH2: Activity | AJ2: Energy | AK2: Flux | AL2: Coefficient | AM2: Activity | AO2: Energy | AP2: Flux | AQ2: Coefficient | AR2: Activity | AT2: Energy | AU2: Flux | AV2: Coefficient | AW2: Activity
A3: 1.39e-11 | B3: 0 | C3: 0 | D3: =B3*C3 -> 0 | F3: 1.39e-11 | G3: 0 | H3: 0 | I3: =G3*H3 -> 0 | K3: 1.39e-11 | L3: 0 | M3: 0 | N3: =L3*M3 -> 0 | P3: 1.39e-11 | Q3: 0 | R3: 0 | S3: =Q3*R3 -> 0 | U3: 1.39e-11 | V3: 0 | W3: 0 | X3: =V3*W3 -> 0 | Z3: 1.39e-11 | AA3: 0 | AB3: 0 | AC3: =AA3*AB3 -> 0 | AE3: 1.39e-11 | AF3: 0 | AG3: 0 | AH3: =AF3*AG3 -> 0 | AJ3: 1.39e-11 | AK3: 0 | AL3: 0 | AM3: =AK3*AL3 -> 0 | AO3: 1.39e-11 | AP3: 0 | AQ3: 0 | AR3: =AP3*AQ3 -> 0 | AT3: 1.39e-11 | AU3: 0 | AV3: 0 | AW3: =AU3*AV3 -> 0
A4: 3.78e-11 | B4: 0 | C4: 0.58526818 | D4: =B4*C4 -> 0 | F4: 3.78e-11 | G4: 0 | H4: 0 | I4: =G4*H4 -> 0 | K4: 3.78e-11 | L4: 0 | M4: 0 | N4: =L4*M4 -> 0 | P4: 3.78e-11 | Q4: 0 | R4: 0 | S4: =Q4*R4 -> 0 | U4: 3.78e-11 | V4: 0 | W4: 0 | X4: =V4*W4 -> 0 | Z4: 3.78e-11 | AA4: 0 | AB4: 0 | AC4: =AA4*AB4 -> 0 | AE4: 3.78e-11 | AF4: 0 | AG4: 0 | AH4: =AF4*AG4 -> 0 | AJ4: 3.78e-11 | AK4: 0 | AL4: 0.086655104 | AM4: =AK4*AL4 -> 0 | AO4: 3.78e-11 | AP4: 0 | AQ4: 0.0011435216 | AR4: =AP4*AQ4 -> 0 | AT4: 3.78e-11 | AU4: 0 | AV4: 0 | AW4: =AU4*AV4 -> 0
A5: 1.03e-10 | B5: 0 | C5: 0.35843542 | D5: =B5*C5 -> 0 | F5: 1.03e-10 | G5: 0 | H5: 0 | I5: =G5*H5 -> 0 | K5: 1.03e-10 | L5: 0 | M5: 0 | N5: =L5*M5 -> 0 | P5: 1.03e-10 | Q5: 0 | R5: 0 | S5: =Q5*R5 -> 0 | U5: 1.03e-10 | V5: 0 | W5: 0 | X5: =V5*W5 -> 0 | Z5: 1.03e-10 | AA5: 0 | AB5: 0 | AC5: =AA5*AB5 -> 0 | AE5: 1.03e-10 | AF5: 0 | AG5: 0 | AH5: =AF5*AG5 -> 0 | AJ5: 1.03e-10 | AK5: 0 | AL5: 0.053069282 | AM5: =AK5*AL5 -> 0 | AO5: 1.03e-10 | AP5: 0 | AQ5: 0.00070031598 | AR5: =AP5*AQ5 -> 0 | AT5: 1.03e-10 | AU5: 0 | AV5: 0 | AW5: =AU5*AV5 -> 0
A6: 2.79e-10 | B6: 0 | C6: 0.21952152 | D6: =B6*C6 -> 0 | F6: 2.79e-10 | G6: 0 | H6: 0 | I6: =G6*H6 -> 0 | K6: 2.79e-10 | L6: 0 | M6: 0 | N6: =L6*M6 -> 0 | P6: 2.79e-10 | Q6: 0 | R6: 0 | S6: =Q6*R6 -> 0 | U6: 2.79e-10 | V6: 0 | W6: 0 | X6: =V6*W6 -> 0 | Z6: 2.79e-10 | AA6: 0 | AB6: 0 | AC6: =AA6*AB6 -> 0 | AE6: 2.79e-10 | AF6: 0 | AG6: 0 | AH6: =AF6*AG6 -> 0 | AJ6: 2.79e-10 | AK6: 0 | AL6: 0.032500678 | AM6: =AK6*AL6 -> 0 | AO6: 2.79e-10 | AP6: 0 | AQ6: 0.0004288884 | AR6: =AP6*AQ6 -> 0 | AT6: 2.79e-10 | AU6: 0 | AV6: 0 | AW6: =AU6*AV6 -> 0
A7: 7.58e-10 | B7: 0 | C7: 0.13147263 | D7: =B7*C7 -> 0 | F7: 7.58e-10 | G7: 0 | H7: 0 | I7: =G7*H7 -> 0 | K7: 7.58e-10 | L7: 0 | M7: 0 | N7: =L7*M7 -> 0 | P7: 7.58e-10 | Q7: 0 | R7: 0 | S7: =Q7*R7 -> 0 | U7: 7.58e-10 | V7: 0 | W7: 0 | X7: =V7*W7 -> 0 | Z7: 7.58e-10 | AA7: 0 | AB7: 0 | AC7: =AA7*AB7 -> 0 | AE7: 7.58e-10 | AF7: 0 | AG7: 0 | AH7: =AF7*AG7 -> 0 | AJ7: 7.58e-10 | AK7: 0 | AL7: 0.01946265 | AM7: =AK7*AL7 -> 0 | AO7: 7.58e-10 | AP7: 0 | AQ7: 0.00025683705 | AR7: =AP7*AQ7 -> 0 | AT7: 7.58e-10 | AU7: 0 | AV7: 0 | AW7: =AU7*AV7 -> 0
A8: 2.06e-09 | B8: 767.279 | C8: 0.078425803 | D8: =B8*C8 -> 60.174472 | F8: 2.06e-09 | G8: 767.279 | H8: 0 | I8: =G8*H8 -> 0 | K8: 2.06e-09 | L8: 767.279 | M8: 0 | N8: =L8*M8 -> 0 | P8: 2.06e-09 | Q8: 767.279 | R8: 0 | S8: =Q8*R8 -> 0 | U8: 2.06e-09 | V8: 767.279 | W8: 0 | X8: =V8*W8 -> 0 | Z8: 2.06e-09 | AA8: 767.279 | AB8: 0 | AC8: =AA8*AB8 -> 0 | AE8: 2.06e-09 | AF8: 767.279 | AG8: 0 | AH8: =AF8*AG8 -> 0 | AJ8: 2.06e-09 | AK8: 767.279 | AL8: 0.011606163 | AM8: =AK8*AL8 -> 8.9051655 | AO8: 2.06e-09 | AP8: 767.279 | AQ8: 0.00015316319 | AR8: =AP8*AQ8 -> 0.1175189 | AT8: 2.06e-09 | AU8: 767.279 | AV8: 0 | AW8: =AU8*AV8 -> 0
A9: 5.6e-09 | B9: 1662.51 | C9: 0.048068049 | D9: =B9*C9 -> 79.913612 | F9: 5.6e-09 | G9: 1662.51 | H9: 0 | I9: =G9*H9 -> 0 | K9: 5.6e-09 | L9: 1662.51 | M9: 0 | N9: =L9*M9 -> 0 | P9: 5.6e-09 | Q9: 1662.51 | R9: 0 | S9: =Q9*R9 -> 0 | U9: 5.6e-09 | V9: 1662.51 | W9: 0 | X9: =V9*W9 -> 0 | Z9: 5.6e-09 | AA9: 1662.51 | AB9: 0 | AC9: =AA9*AB9 -> 0 | AE9: 5.6e-09 | AF9: 1662.51 | AG9: 0 | AH9: =AF9*AG9 -> 0 | AJ9: 5.6e-09 | AK9: 1662.51 | AL9: 0.0071076524 | AM9: =AK9*AL9 -> 11.816543 | AO9: 5.6e-09 | AP9: 1662.51 | AQ9: 9.3802658e-05 | AR9: =AP9*AQ9 -> 0.15594786 | AT9: 5.6e-09 | AU9: 1662.51 | AV9: 0 | AW9: =AU9*AV9 -> 0
A10: 1.52e-08 | B10: 6194.83 | C10: 0.029502587 | D10: =B10*C10 -> 182.76351 | F10: 1.52e-08 | G10: 6194.83 | H10: 0 | I10: =G10*H10 -> 0 | K10: 1.52e-08 | L10: 6194.83 | M10: 0 | N10: =L10*M10 -> 0 | P10: 1.52e-08 | Q10: 6194.83 | R10: 0 | S10: =Q10*R10 -> 0 | U10: 1.52e-08 | V10: 6194.83 | W10: 0 | X10: =V10*W10 -> 0 | Z10: 1.52e-08 | AA10: 6194.83 | AB10: 0 | AC10: =AA10*AB10 -> 0 | AE10: 1.52e-08 | AF10: 6194.83 | AG10: 0 | AH10: =AF10*AG10 -> 0 | AJ10: 1.52e-08 | AK10: 6194.83 | AL10: 0.0043527575 | AM10: =AK10*AL10 -> 26.964593 | AO10: 1.52e-08 | AP10: 6194.83 | AQ10: 5.7450799e-05 | AR10: =AP10*AQ10 -> 0.35589794 | AT10: 1.52e-08 | AU10: 6194.83 | AV10: 0 | AW10: =AU10*AV10 -> 0
A11: 4.14e-08 | B11: 29258.8 | C11: 0.017801229 | D11: =B11*C11 -> 520.84259 | F11: 4.14e-08 | G11: 29258.8 | H11: 0 | I11: =G11*H11 -> 0 | K11: 4.14e-08 | L11: 29258.8 | M11: 0 | N11: =L11*M11 -> 0 | P11: 4.14e-08 | Q11: 29258.8 | R11: 0 | S11: =Q11*R11 -> 0 | U11: 4.14e-08 | V11: 29258.8 | W11: 0 | X11: =V11*W11 -> 0 | Z11: 4.14e-08 | AA11: 29258.8 | AB11: 0 | AC11: =AA11*AB11 -> 0 | AE11: 4.14e-08 | AF11: 29258.8 | AG11: 0 | AH11: =AF11*AG11 -> 0 | AJ11: 4.14e-08 | AK11: 29258.8 | AL11: 0.002610751 | AM11: =AK11*AL11 -> 76.38744 | AO11: 4.14e-08 | AP11: 29258.8 | AQ11: 3.446762e-05 | AR11: =AP11*AQ11 -> 1.0084812 | AT11: 4.14e-08 | AU11: 29258.8 | AV11: 0 | AW11: =AU11*AV11 -> 0
A12: 1.13e-07 | B12: 59368.7 | C12: 0.011029391 | D12: =B12*C12 -> 654.8006 | F12: 1.13e-07 | G12: 59368.7 | H12: 0 | I12: =G12*H12 -> 0 | K12: 1.13e-07 | L12: 59368.7 | M12: 0 | N12: =L12*M12 -> 0 | P12: 1.13e-07 | Q12: 59368.7 | R12: 0 | S12: =Q12*R12 -> 0 | U12: 1.13e-07 | V12: 59368.7 | W12: 0 | X12: =V12*W12 -> 0 | Z12: 1.13e-07 | AA12: 59368.7 | AB12: 0 | AC12: =AA12*AB12 -> 0 | AE12: 1.13e-07 | AF12: 59368.7 | AG12: 0 | AH12: =AF12*AG12 -> 0 | AJ12: 1.13e-07 | AK12: 59368.7 | AL12: 0.0015623722 | AM12: =AK12*AL12 -> 92.756008 | AO12: 1.13e-07 | AP12: 59368.7 | AQ12: 2.0630598e-05 | AR12: =AP12*AQ12 -> 1.2248118 | AT12: 1.13e-07 | AU12: 59368.7 | AV12: 0 | AW12: =AU12*AV12 -> 0
A13: 3.06e-07 | B13: 87786.6 | C13: 0.0070425019 | D13: =B13*C13 -> 618.23729 | F13: 3.06e-07 | G13: 87786.6 | H13: 0 | I13: =G13*H13 -> 0 | K13: 3.06e-07 | L13: 87786.6 | M13: 0 | N13: =L13*M13 -> 0 | P13: 3.06e-07 | Q13: 87786.6 | R13: 0 | S13: =Q13*R13 -> 0 | U13: 3.06e-07 | V13: 87786.6 | W13: 0 | X13: =V13*W13 -> 0 | Z13: 3.06e-07 | AA13: 87786.6 | AB13: 0 | AC13: =AA13*AB13 -> 0 | AE13: 3.06e-07 | AF13: 87786.6 | AG13: 0 | AH13: =AF13*AG13 -> 0 | AJ13: 3.06e-07 | AK13: 87786.6 | AL13: 0.00095691324 | AM13: =AK13*AL13 -> 84.00416 | AO13: 3.06e-07 | AP13: 87786.6 | AQ13: 1.2652057e-05 | AR13: =AP13*AQ13 -> 1.110681 | AT13: 3.06e-07 | AU13: 87786.6 | AV13: 0 | AW13: =AU13*AV13 -> 0
A14: 8.32e-07 | B14: 138307 | C14: 0.0048242872 | D14: =B14*C14 -> 667.23269 | F14: 8.32e-07 | G14: 138307 | H14: 0 | I14: =G14*H14 -> 0 | K14: 8.32e-07 | L14: 138307 | M14: 0 | N14: =L14*M14 -> 0 | P14: 8.32e-07 | Q14: 138307 | R14: 0 | S14: =Q14*R14 -> 0 | U14: 8.32e-07 | V14: 138307 | W14: 0 | X14: =V14*W14 -> 0 | Z14: 8.32e-07 | AA14: 138307 | AB14: 0 | AC14: =AA14*AB14 -> 0 | AE14: 8.32e-07 | AF14: 138307 | AG14: 0 | AH14: =AF14*AG14 -> 0 | AJ14: 8.32e-07 | AK14: 138307 | AL14: 0.00058577418 | AM14: =AK14*AL14 -> 81.01667 | AO14: 8.32e-07 | AP14: 138307 | AQ14: 7.7770486e-06 | AR14: =AP14*AQ14 -> 1.0756203 | AT14: 8.32e-07 | AU14: 138307 | AV14: 0 | AW14: =AU14*AV14 -> 0
... A62: 30 | B62: 0 | C62: 1.7879307e-09 | D62: =B62*C62 -> 0 | F62: 30 | G62: 0 | H62: 4.0764804e-05 | I62: =G62*H62 -> 0 | K62: 30 | L62: 0 | M62: 0 | N62: =L62*M62 -> 0 | P62: 30 | Q62: 0 | R62: 0 | S62: =Q62*R62 -> 0 | U62: 30 | V62: 0 | W62: 1.2992026e-06 | X62: =V62*W62 -> 0 | Z62: 30 | AA62: 0 | AB62: 0 | AC62: =AA62*AB62 -> 0 | AE62: 30 | AF62: 0 | AG62: 0 | AH62: =AF62*AG62 -> 0 | AJ62: 30 | AK62: 0 | AL62: 0 | AM62: =AK62*AL62 -> 0 | AO62: 30 | AP62: 0 | AQ62: 0 | AR62: =AP62*AQ62 -> 0 | AT62: 30 | AU62: 0 | AV62: 0 | AW62: =AU62*AV62 -> 0
A64: sum | D64: =SUM(D3:D63) -> 173185.92 | I64: =SUM(I3:I63) -> 16.684162 | N64: =SUM(N3:N63) -> 40.4161 | S64: =SUM(S3:S63) -> 23.184918 | X64: =SUM(X3:X63) -> 4.5851116 | AC64: =SUM(AC3:AC63) -> 0.17522741 | AH64: =SUM(AH3:AH63) -> 5.0195443 | AM64: =SUM(AM3:AM63) -> 534.37552 | AR64: =SUM(AR3:AR63) -> 10.244338 | AW64: =SUM(AW3:AW63) -> 25.282527
A70: activity error | B70: =ABS((D64-activity_Ami!D242)/activity_Ami!D242) -> 4.1185984 | F70: activity error | G70: =ABS((I64-activity_Ami!I242)/activity_Ami!I242) -> 0.12937168 | K70: activity error | L70: =ABS((N64-activity_Ami!N242)/activity_Ami!N242) -> 0.15743065 | P70: activity error | Q70: =ABS((S64-activity_Ami!S242)/activity_Ami!S242) -> 0.11597056 | U70: activity error | V70: =ABS((X64-activity_Ami!X242)/activity_Ami!X242) -> 0.11974572 | Z70: activity error | AA70: =ABS((AC64-activity_Ami!AC242)/activity_Ami!AC242) -> 0.16227228 | AE70: activity error | AF70: =ABS((AH64-activity_Ami!AH242)/activity_Ami!AH242) -> 0.15063936 | AJ70: activity error | AK70: =ABS((AM64-activity_Ami!AM242)/activity_Ami!AM242) -> 0.25068693 | AO70: activity error | AP70: =ABS((AR64-activity_Ami!AR242)/activity_Ami!AR242) -> 0.023255954 | AT70: activity error | AU70: =ABS((AW64-activity_Ami!AW242)/activity_Ami!AW242) -> 0.11934829
A77: ri | B77: =activity_Ami!D242/D64 -> 0.19536598 | F77: ri | G77: =activity_Ami!I242/I64 -> 0.88544809 | K77: ri | L77: =activity_Ami!N242/N64 -> 0.86398265 | P77: ri | Q77: =activity_Ami!S242/S64 -> 0.89608098 | U77: ri | V77: =activity_Ami!X242/X64 -> 0.8930599 | Z77: ri | AA77: =activity_Ami!AC242/AC64 -> 0.8603836 | AE77: ri | AF77: =activity_Ami!AH242/AH64 -> 0.86908204 | AJ77: ri | AK77: =activity_Ami!AM242/AM64 -> 1.3345557 | AO77: ri | AP77: =activity_Ami!AR242/AR64 -> 1.0238097 | AT77: ri | AU77: =activity_Ami!AW242/AW64 -> 0.89337698
A83: ERRE | B83: =0.1*(B70+G70+L70+Q70+V70+AA70+AF70+AK70+AP70+AU70) -> 0.53473198
A91: DEV | B91: =(((B77-1)^2+(G77-1)^2+(L77-1)^2+(Q77-1)^2+(V77-1)^2+(AA77-1)^2+(AF77-1)^2+(AK77-1)^2+(AP77-1)^2+(AU77-1)^2)/9)^0.5 -> 0.30944201

Sheet 60groups_result
A1: Au-197 | F1: Fe-56 | K1: Al-27 | P1: Ni-58 | U1: Fe-54 | Z1: Cu-63 | AE1: Ti-48 | AJ1: Na-23 | AO1: Co-59 | AT1: S-32
A2: Energy | B2: Flux | C2: Coefficient | D2: Activity | F2: Energy | G2: Flux | H2: Coefficient | I2: Activity | K2: Energy | L2: Flux | M2: Coefficient | N2: Activity | P2: Energy | Q2: Flux | R2: Coefficient | S2: Activity | U2: Energy | V2: Flux | W2: Coefficient | X2: Activity | Z2: Energy | AA2: Flux | AB2: Coefficient | AC2: Activity | AE2: Energy | AF2: Flux | AG2: Coefficient | AH2: Activity | AJ2: Energy | AK2: Flux | AL2: Coefficient | AM2: Activity | AO2: Energy | AP2: Flux | AQ2: Coefficient | AR2: Activity | AT2: Energy | AU2: Flux | AV2: Coefficient | AW2: Activity
A3: 1.39e-11 | B3: 0 | C3: 0 | D3: =B3*C3 -> 0 | F3: 1.39e-11 | G3: 0 | H3: 0 | I3: =G3*H3 -> 0 | K3: 1.39e-11 | L3: 0 | M3: 0 | N3: =L3*M3 -> 0 | P3: 1.39e-11 | Q3: 0 | R3: 0 | S3: =Q3*R3 -> 0 | U3: 1.39e-11 | V3: 0 | W3: 0 | X3: =V3*W3 -> 0 | Z3: 1.39e-11 | AA3: 0 | AB3: 0 | AC3: =AA3*AB3 -> 0 | AE3: 1.39e-11 | AF3: 0 | AG3: 0 | AH3: =AF3*AG3 -> 0 | AJ3: 1.39e-11 | AK3: 0 | AL3: 0 | AM3: =AK3*AL3 -> 0 | AO3: 1.39e-11 | AP3: 0 | AQ3: 0 | AR3: =AP3*AQ3 -> 0 | AT3: 1.39e-11 | AU3: 0 | AV3: 0 | AW3: =AU3*AV3 -> 0
A4: 3.78e-11 | B4: 0 | C4: 0.58526818 | D4: =B4*C4 -> 0 | F4: 3.78e-11 | G4: 0 | H4: 0 | I4: =G4*H4 -> 0 | K4: 3.78e-11 | L4: 0 | M4: 0 | N4: =L4*M4 -> 0 | P4: 3.78e-11 | Q4: 0 | R4: 0 | S4: =Q4*R4 -> 0 | U4: 3.78e-11 | V4: 0 | W4: 0 | X4: =V4*W4 -> 0 | Z4: 3.78e-11 | AA4: 0 | AB4: 0 | AC4: =AA4*AB4 -> 0 | AE4: 3.78e-11 | AF4: 0 | AG4: 0 | AH4: =AF4*AG4 -> 0 | AJ4: 3.78e-11 | AK4: 0 | AL4: 0.086655104 | AM4: =AK4*AL4 -> 0 | AO4: 3.78e-11 | AP4: 0 | AQ4: 0.0011435216 | AR4: =AP4*AQ4 -> 0 | AT4: 3.78e-11 | AU4: 0 | AV4: 0 | AW4: =AU4*AV4 -> 0
A5: 1.03e-10 | B5: 0 | C5: 0.35843542 | D5: =B5*C5 -> 0 | F5: 1.03e-10 | G5: 0 | H5: 0 | I5: =G5*H5 -> 0 | K5: 1.03e-10 | L5: 0 | M5: 0 | N5: =L5*M5 -> 0 | P5: 1.03e-10 | Q5: 0 | R5: 0 | S5: =Q5*R5 -> 0 | U5: 1.03e-10 | V5: 0 | W5: 0 | X5: =V5*W5 -> 0 | Z5: 1.03e-10 | AA5: 0 | AB5: 0 | AC5: =AA5*AB5 -> 0 | AE5: 1.03e-10 | AF5: 0 | AG5: 0 | AH5: =AF5*AG5 -> 0 | AJ5: 1.03e-10 | AK5: 0 | AL5: 0.053069282 | AM5: =AK5*AL5 -> 0 | AO5: 1.03e-10 | AP5: 0 | AQ5: 0.00070031598 | AR5: =AP5*AQ5 -> 0 | AT5: 1.03e-10 | AU5: 0 | AV5: 0 | AW5: =AU5*AV5 -> 0
A6: 2.79e-10 | B6: 0 | C6: 0.21952152 | D6: =B6*C6 -> 0 | F6: 2.79e-10 | G6: 0 | H6: 0 | I6: =G6*H6 -> 0 | K6: 2.79e-10 | L6: 0 | M6: 0 | N6: =L6*M6 -> 0 | P6: 2.79e-10 | Q6: 0 | R6: 0 | S6: =Q6*R6 -> 0 | U6: 2.79e-10 | V6: 0 | W6: 0 | X6: =V6*W6 -> 0 | Z6: 2.79e-10 | AA6: 0 | AB6: 0 | AC6: =AA6*AB6 -> 0 | AE6: 2.79e-10 | AF6: 0 | AG6: 0 | AH6: =AF6*AG6 -> 0 | AJ6: 2.79e-10 | AK6: 0 | AL6: 0.032500678 | AM6: =AK6*AL6 -> 0 | AO6: 2.79e-10 | AP6: 0 | AQ6: 0.0004288884 | AR6: =AP6*AQ6 -> 0 | AT6: 2.79e-10 | AU6: 0 | AV6: 0 | AW6: =AU6*AV6 -> 0
A7: 7.58e-10 | B7: 0 | C7: 0.13147263 | D7: =B7*C7 -> 0 | F7: 7.58e-10 | G7: 0 | H7: 0 | I7: =G7*H7 -> 0 | K7: 7.58e-10 | L7: 0 | M7: 0 | N7: =L7*M7 -> 0 | P7: 7.58e-10 | Q7: 0 | R7: 0 | S7: =Q7*R7 -> 0 | U7: 7.58e-10 | V7: 0 | W7: 0 | X7: =V7*W7 -> 0 | Z7: 7.58e-10 | AA7: 0 | AB7: 0 | AC7: =AA7*AB7 -> 0 | AE7: 7.58e-10 | AF7: 0 | AG7: 0 | AH7: =AF7*AG7 -> 0 | AJ7: 7.58e-10 | AK7: 0 | AL7: 0.01946265 | AM7: =AK7*AL7 -> 0 | AO7: 7.58e-10 | AP7: 0 | AQ7: 0.00025683705 | AR7: =AP7*AQ7 -> 0 | AT7: 7.58e-10 | AU7: 0 | AV7: 0 | AW7: =AU7*AV7 -> 0
A8: 2.06e-09 | B8: 22479.421 | C8: 0.078425803 | D8: =B8*C8 -> 1762.9667 | F8: 2.06e-09 | G8: 22479.421 | H8: 0 | I8: =G8*H8 -> 0 | K8: 2.06e-09 | L8: 22479.421 | M8: 0 | N8: =L8*M8 -> 0 | P8: 2.06e-09 | Q8: 22479.421 | R8: 0 | S8: =Q8*R8 -> 0 | U8: 2.06e-09 | V8: 22479.421 | W8: 0 | X8: =V8*W8 -> 0 | Z8: 2.06e-09 | AA8: 22479.421 | AB8: 0 | AC8: =AA8*AB8 -> 0 | AE8: 2.06e-09 | AF8: 22479.421 | AG8: 0 | AH8: =AF8*AG8 -> 0 | AJ8: 2.06e-09 | AK8: 22479.421 | AL8: 0.011606163 | AM8: =AK8*AL8 -> 260.89984 | AO8: 2.06e-09 | AP8: 22479.421 | AQ8: 0.00015316319 | AR8: =AP8*AQ8 -> 3.4430198 | AT8: 2.06e-09 | AU8: 22479.421 | AV8: 0 | AW8: =AU8*AV8 -> 0
A9: 5.6e-09 | B9: 13766.151 | C9: 0.048068049 | D9: =B9*C9 -> 661.71203 | F9: 5.6e-09 | G9: 13766.151 | H9: 0 | I9: =G9*H9 -> 0 | K9: 5.6e-09 | L9: 13766.151 | M9: 0 | N9: =L9*M9 -> 0 | P9: 5.6e-09 | Q9: 13766.151 | R9: 0 | S9: =Q9*R9 -> 0 | U9: 5.6e-09 | V9: 13766.151 | W9: 0 | X9: =V9*W9 -> 0 | Z9: 5.6e-09 | AA9: 13766.151 | AB9: 0 | AC9: =AA9*AB9 -> 0 | AE9: 5.6e-09 | AF9: 13766.151 | AG9: 0 | AH9: =AF9*AG9 -> 0 | AJ9: 5.6e-09 | AK9: 13766.151 | AL9: 0.0071076524 | AM9: =AK9*AL9 -> 97.845019 | AO9: 5.6e-09 | AP9: 13766.151 | AQ9: 9.3802658e-05 | AR9: =AP9*AQ9 -> 1.2913016 | AT9: 5.6e-09 | AU9: 13766.151 | AV9: 0 | AW9: =AU9*AV9 -> 0
A10: 1.52e-08 | B10: 8429.9302 | C10: 0.029502587 | D10: =B10*C10 -> 248.70475 | F10: 1.52e-08 | G10: 8429.9302 | H10: 0 | I10: =G10*H10 -> 0 | K10: 1.52e-08 | L10: 8429.9302 | M10: 0 | N10: =L10*M10 -> 0 | P10: 1.52e-08 | Q10: 8429.9302 | R10: 0 | S10: =Q10*R10 -> 0 | U10: 1.52e-08 | V10: 8429.9302 | W10: 0 | X10: =V10*W10 -> 0 | Z10: 1.52e-08 | AA10: 8429.9302 | AB10: 0 | AC10: =AA10*AB10 -> 0 | AE10: 1.52e-08 | AF10: 8429.9302 | AG10: 0 | AH10: =AF10*AG10 -> 0 | AJ10: 1.52e-08 | AK10: 8429.9302 | AL10: 0.0043527575 | AM10: =AK10*AL10 -> 36.693442 | AO10: 1.52e-08 | AP10: 8429.9302 | AQ10: 5.7450799e-05 | AR10: =AP10*AQ10 -> 0.48430623 | AT10: 1.52e-08 | AU10: 8429.9302 | AV10: 0 | AW10: =AU10*AV10 -> 0
A11: 4.14e-08 | B11: 21040.373 | C11: 0.017801229 | D11: =B11*C11 -> 374.54448 | F11: 4.14e-08 | G11: 21040.373 | H11: 0 | I11: =G11*H11 -> 0 | K11: 4.14e-08 | L11: 21040.373 | M11: 0 | N11: =L11*M11 -> 0 | P11: 4.14e-08 | Q11: 21040.373 | R11: 0 | S11: =Q11*R11 -> 0 | U11: 4.14e-08 | V11: 21040.373 | W11: 0 | X11: =V11*W11 -> 0 | Z11: 4.14e-08 | AA11: 21040.373 | AB11: 0 | AC11: =AA11*AB11 -> 0 | AE11: 4.14e-08 | AF11: 21040.373 | AG11: 0 | AH11: =AF11*AG11 -> 0 | AJ11: 4.14e-08 | AK11: 21040.373 | AL11: 0.002610751 | AM11: =AK11*AL11 -> 54.931173 | AO11: 4.14e-08 | AP11: 21040.373 | AQ11: 3.446762e-05 | AR11: =AP11*AQ11 -> 0.72521158 | AT11: 4.14e-08 | AU11: 21040.373 | AV11: 0 | AW11: =AU11*AV11 -> 0
A12: 1.13e-07 | B12: 40790.414 | C12: 0.011029391 | D12: =B12*C12 -> 449.89342 | F12: 1.13e-07 | G12: 40790.414 | H12: 0 | I12: =G12*H12 -> 0 | K12: 1.13e-07 | L12: 40790.414 | M12: 0 | N12: =L12*M12 -> 0 | P12: 1.13e-07 | Q12: 40790.414 | R12: 0 | S12: =Q12*R12 -> 0 | U12: 1.13e-07 | V12: 40790.414 | W12: 0 | X12: =V12*W12 -> 0 | Z12: 1.13e-07 | AA12: 40790.414 | AB12: 0 | AC12: =AA12*AB12 -> 0 | AE12: 1.13e-07 | AF12: 40790.414 | AG12: 0 | AH12: =AF12*AG12 -> 0 | AJ12: 1.13e-07 | AK12: 40790.414 | AL12: 0.0015623722 | AM12: =AK12*AL12 -> 63.729811 | AO12: 1.13e-07 | AP12: 40790.414 | AQ12: 2.0630598e-05 | AR12: =AP12*AQ12 -> 0.84153063 | AT12: 1.13e-07 | AU12: 40790.414 | AV12: 0 | AW12: =AU12*AV12 -> 0
A13: 3.06e-07 | B13: 59665.043 | C13: 0.0070425019 | D13: =B13*C13 -> 420.19118 | F13: 3.06e-07 | G13: 59665.043 | H13: 0 | I13: =G13*H13 -> 0 | K13: 3.06e-07 | L13: 59665.043 | M13: 0 | N13: =L13*M13 -> 0 | P13: 3.06e-07 | Q13: 59665.043 | R13: 0 | S13: =Q13*R13 -> 0 | U13: 3.06e-07 | V13: 59665.043 | W13: 0 | X13: =V13*W13 -> 0 | Z13: 3.06e-07 | AA13: 59665.043 | AB13: 0 | AC13: =AA13*AB13 -> 0 | AE13: 3.06e-07 | AF13: 59665.043 | AG13: 0 | AH13: =AF13*AG13 -> 0 | AJ13: 3.06e-07 | AK13: 59665.043 | AL13: 0.00095691324 | AM13: =AK13*AL13 -> 57.09427 | AO13: 3.06e-07 | AP13: 59665.043 | AQ13: 1.2652057e-05 | AR13: =AP13*AQ13 -> 0.75488552 | AT13: 3.06e-07 | AU13: 59665.043 | AV13: 0 | AW13: =AU13*AV13 -> 0
A14: 8.32e-07 | B14: 93549.636 | C14: 0.0048242872 | D14: =B14*C14 -> 451.31031 | F14: 8.32e-07 | G14: 93549.636 | H14: 0 | I14: =G14*H14 -> 0 | K14: 8.32e-07 | L14: 93549.636 | M14: 0 | N14: =L14*M14 -> 0 | P14: 8.32e-07 | Q14: 93549.636 | R14: 0 | S14: =Q14*R14 -> 0 | U14: 8.32e-07 | V14: 93549.636 | W14: 0 | X14: =V14*W14 -> 0 | Z14: 8.32e-07 | AA14: 93549.636 | AB14: 0 | AC14: =AA14*AB14 -> 0 | AE14: 8.32e-07 | AF14: 93549.636 | AG14: 0 | AH14: =AF14*AG14 -> 0 | AJ14: 8.32e-07 | AK14: 93549.636 | AL14: 0.00058577418 | AM14: =AK14*AL14 -> 54.798961 | AO14: 8.32e-07 | AP14: 93549.636 | AQ14: 7.7770486e-06 | AR14: =AP14*AQ14 -> 0.72754006 | AT14: 8.32e-07 | AU14: 93549.636 | AV14: 0 | AW14: =AU14*AV14 -> 0
... A62: 30 | B62: 0 | C62: 1.7879307e-09 | D62: =B62*C62 -> 0 | F62: 30 | G62: 0 | H62: 4.0764804e-05 | I62: =G62*H62 -> 0 | K62: 30 | L62: 0 | M62: 0 | N62: =L62*M62 -> 0 | P62: 30 | Q62: 0 | R62: 0 | S62: =Q62*R62 -> 0 | U62: 30 | V62: 0 | W62: 1.2992026e-06 | X62: =V62*W62 -> 0 | Z62: 30 | AA62: 0 | AB62: 0 | AC62: =AA62*AB62 -> 0 | AE62: 30 | AF62: 0 | AG62: 0 | AH62: =AF62*AG62 -> 0 | AJ62: 30 | AK62: 0 | AL62: 0 | AM62: =AK62*AL62 -> 0 | AO62: 30 | AP62: 0 | AQ62: 0 | AR62: =AP62*AQ62 -> 0 | AT62: 30 | AU62: 0 | AV62: 0 | AW62: =AU62*AV62 -> 0
A64: sum | D64: =SUM(D3:D63) -> 33834.665 | I64: =SUM(I3:I63) -> 11.38711 | N64: =SUM(N3:N63) -> 27.612924 | S64: =SUM(S3:S63) -> 15.718121 | X64: =SUM(X3:X63) -> 3.1092123 | AC64: =SUM(AC3:AC63) -> 0.11952201 | AH64: =SUM(AH3:AH63) -> 3.4368296 | AM64: =SUM(AM3:AM63) -> 705.63258 | AR64: =SUM(AR3:AR63) -> 11.05317 | AW64: =SUM(AW3:AW63) -> 17.141987
A70: activity error | B70: =ABS((D64-activity_Ami!D242)/activity_Ami!D242) -> 8.1285687e-07 | F70: activity error | G70: =ABS((I64-activity_Ami!I242)/activity_Ami!I242) -> 0.22919237 | K70: activity error | L70: =ABS((N64-activity_Ami!N242)/activity_Ami!N242) -> 0.20922492 | P70: activity error | Q70: =ABS((S64-activity_Ami!S242)/activity_Ami!S242) -> 0.24343229 | U70: activity error | V70: =ABS((X64-activity_Ami!X242)/activity_Ami!X242) -> 0.24068866 | Z70: activity error | AA70: =ABS((AC64-activity_Ami!AC242)/activity_Ami!AC242) -> 0.20721812 | AE70: activity error | AF70: =ABS((AH64-activity_Ami!AH242)/activity_Ami!AH242) -> 0.21216924 | AJ70: activity error | AK70: =ABS((AM64-activity_Ami!AM242)/activity_Ami!AM242) -> 0.010546534 | AO70: activity error | AP70: =ABS((AR64-activity_Ami!AR242)/activity_Ami!AR242) -> 0.053862015 | AT70: activity error | AU70: =ABS((AW64-activity_Ami!AW242)/activity_Ami!AW242) -> 0.24106268
A77: ri | B77: =activity_Ami!D242/D64 -> 0.99999919 | F77: ri | G77: =activity_Ami!I242/I64 -> 1.2973406 | K77: ri | L77: =activity_Ami!N242/N64 -> 1.2645821 | P77: ri | Q77: =activity_Ami!S242/S64 -> 1.3217588 | U77: ri | V77: =activity_Ami!X242/X64 -> 1.3169828 | Z77: ri | AA77: =activity_Ami!AC242/AC64 -> 1.261381 | AE77: ri | AF77: =activity_Ami!AH242/AH64 -> 1.2693082 | AJ77: ri | AK77: =activity_Ami!AM242/AM64 -> 1.0106589 | AO77: ri | AP77: =activity_Ami!AR242/AR64 -> 0.94889083 | AT77: ri | AU77: =activity_Ami!AW242/AW64 -> 1.3176319
A82: ERRE | B82: =0.1*(B70+G70+L70+Q70+V70+AA70+AF70+AK70+AP70+AU70) -> 0.16473977
A91: DEV | B91: =(((B77-1)^2+(G77-1)^2+(L77-1)^2+(Q77-1)^2+(V77-1)^2+(AA77-1)^2+(AF77-1)^2+(AK77-1)^2+(AP77-1)^2+(AU77-1)^2)/9)^0.5 -> 0.25967599

Sheet 113groups_prior
A1: Au-197 | F1: Fe-56 | K1: Al-27 | P1: Ni-58 | U1: Fe-54 | Z1: Cu-63 | AE1: Ti-48 | AJ1: Na-23 | AO1: Co-59 | AT1: S-32
A2: Energy | B2: Flux | C2: Coefficient | D2: Activity | F2: Energy | G2: Flux | H2: Coefficient | I2: Activity | K2: Energy | L2: Flux | M2: Coefficient | N2: Activity | P2: Energy | Q2: Flux | R2: Coefficient | S2: Activity | U2: Energy | V2: Flux | W2: Coefficient | X2: Activity | Z2: Energy | AA2: Flux | AB2: Coefficient | AC2: Activity | AE2: Energy | AF2: Flux | AG2: Coefficient | AH2: Activity | AJ2: Energy | AK2: Flux | AL2: Coefficient | AM2: Activity | AO2: Energy | AP2: Flux | AQ2: Coefficient | AR2: Activity | AT2: Energy | AU2: Flux | AV2: Coefficient | AW2: Activity
A3: 1e-11 | B3: 0 | C3: 0 | D3: =B3*C3 -> 0 | F3: 1e-11 | G3: 0 | H3: 0 | I3: =G3*H3 -> 0 | K3: 1e-11 | L3: 0 | M3: 0 | N3: =L3*M3 -> 0 | P3: 1e-11 | Q3: 0 | R3: 0 | S3: =Q3*R3 -> 0 | U3: 1e-11 | V3: 0 | W3: 0 | X3: =V3*W3 -> 0 | Z3: 1e-11 | AA3: 0 | AB3: 0 | AC3: =AA3*AB3 -> 0 | AE3: 1e-11 | AF3: 0 | AG3: 0 | AH3: =AF3*AG3 -> 0 | AJ3: 1e-11 | AK3: 0 | AL3: 0 | AM3: =AK3*AL3 -> 0 | AO3: 1e-11 | AP3: 0 | AQ3: 0 | AR3: =AP3*AQ3 -> 0 | AT3: 1e-11 | AU3: 0 | AV3: 0 | AW3: =AU3*AV3 -> 0
A4: 1.585e-11 | B4: 0 | C4: 0.79894358 | D4: =B4*C4 -> 0 | F4: 1.585e-11 | G4: 0 | H4: 0 | I4: =G4*H4 -> 0 | K4: 1.585e-11 | L4: 0 | M4: 0 | N4: =L4*M4 -> 0 | P4: 1.585e-11 | Q4: 0 | R4: 0 | S4: =Q4*R4 -> 0 | U4: 1.585e-11 | V4: 0 | W4: 0 | X4: =V4*W4 -> 0 | Z4: 1.585e-11 | AA4: 0 | AB4: 0 | AC4: =AA4*AB4 -> 0 | AE4: 1.585e-11 | AF4: 0 | AG4: 0 | AH4: =AF4*AG4 -> 0 | AJ4: 1.585e-11 | AK4: 0 | AL4: 0.11829256 | AM4: =AK4*AL4 -> 0 | AO4: 1.585e-11 | AP4: 0 | AQ4: 0.0015610146 | AR4: =AP4*AQ4 -> 0 | AT4: 1.585e-11 | AU4: 0 | AV4: 0 | AW4: =AU4*AV4 -> 0
A5: 2.512e-11 | B5: 0 | C5: 0.62523349 | D5: =B5*C5 -> 0 | F5: 2.512e-11 | G5: 0 | H5: 0 | I5: =G5*H5 -> 0 | K5: 2.512e-11 | L5: 0 | M5: 0 | N5: =L5*M5 -> 0 | P5: 2.512e-11 | Q5: 0 | R5: 0 | S5: =Q5*R5 -> 0 | U5: 2.512e-11 | V5: 0 | W5: 0 | X5: =V5*W5 -> 0 | Z5: 2.512e-11 | AA5: 0 | AB5: 0 | AC5: =AA5*AB5 -> 0 | AE5: 2.512e-11 | AF5: 0 | AG5: 0 | AH5: =AF5*AG5 -> 0 | AJ5: 2.512e-11 | AK5: 0 | AL5: 0.092572442 | AM5: =AK5*AL5 -> 0 | AO5: 2.512e-11 | AP5: 0 | AQ5: 0.0012216071 | AR5: =AP5*AQ5 -> 0 | AT5: 2.512e-11 | AU5: 0 | AV5: 0 | AW5: =AU5*AV5 -> 0
A6: 3.981e-11 | B6: 0 | C6: 0.48929277 | D6: =B6*C6 -> 0 | F6: 3.981e-11 | G6: 0 | H6: 0 | I6: =G6*H6 -> 0 | K6: 3.981e-11 | L6: 0 | M6: 0 | N6: =L6*M6 -> 0 | P6: 3.981e-11 | Q6: 0 | R6: 0 | S6: =Q6*R6 -> 0 | U6: 3.981e-11 | V6: 0 | W6: 0 | X6: =V6*W6 -> 0 | Z6: 3.981e-11 | AA6: 0 | AB6: 0 | AC6: =AA6*AB6 -> 0 | AE6: 3.981e-11 | AF6: 0 | AG6: 0 | AH6: =AF6*AG6 -> 0 | AJ6: 3.981e-11 | AK6: 0 | AL6: 0.072444631 | AM6: =AK6*AL6 -> 0 | AO6: 3.981e-11 | AP6: 0 | AQ6: 0.00095599865 | AR6: =AP6*AQ6 -> 0 | AT6: 3.981e-11 | AU6: 0 | AV6: 0 | AW6: =AU6*AV6 -> 0
A7: 6.31e-11 | B7: 0 | C7: 0.39206037 | D7: =B7*C7 -> 0 | F7: 6.31e-11 | G7: 0 | H7: 0 | I7: =G7*H7 -> 0 | K7: 6.31e-11 | L7: 0 | M7: 0 | N7: =L7*M7 -> 0 | P7: 6.31e-11 | Q7: 0 | R7: 0 | S7: =Q7*R7 -> 0 | U7: 6.31e-11 | V7: 0 | W7: 0 | X7: =V7*W7 -> 0 | Z7: 6.31e-11 | AA7: 0 | AB7: 0 | AC7: =AA7*AB7 -> 0 | AE7: 6.31e-11 | AF7: 0 | AG7: 0 | AH7: =AF7*AG7 -> 0 | AJ7: 6.31e-11 | AK7: 0 | AL7: 0.058047995 | AM7: =AK7*AL7 -> 0 | AO7: 6.31e-11 | AP7: 0 | AQ7: 0.00076601604 | AR7: =AP7*AQ7 -> 0 | AT7: 6.31e-11 | AU7: 0 | AV7: 0 | AW7: =AU7*AV7 -> 0
A8: 1e-10 | B8: 0 | C8: 0.31471774 | D8: =B8*C8 -> 0 | F8: 1e-10 | G8: 0 | H8: 0 | I8: =G8*H8 -> 0 | K8: 1e-10 | L8: 0 | M8: 0 | N8: =L8*M8 -> 0 | P8: 1e-10 | Q8: 0 | R8: 0 | S8: =Q8*R8 -> 0 | U8: 1e-10 | V8: 0 | W8: 0 | X8: =V8*W8 -> 0 | Z8: 1e-10 | AA8: 0 | AB8: 0 | AC8: =AA8*AB8 -> 0 | AE8: 1e-10 | AF8: 0 | AG8: 0 | AH8: =AF8*AG8 -> 0 | AJ8: 1e-10 | AK8: 0 | AL8: 0.046596237 | AM8: =AK8*AL8 -> 0 | AO8: 1e-10 | AP8: 0 | AQ8: 0.00061489599 | AR8: =AP8*AQ8 -> 0 | AT8: 1e-10 | AU8: 0 | AV8: 0 | AW8: =AU8*AV8 -> 0
A9: 1.585e-10 | B9: 0 | C9: 0.24629436 | D9: =B9*C9 -> 0 | F9: 1.585e-10 | G9: 0 | H9: 0 | I9: =G9*H9 -> 0 | K9: 1.585e-10 | L9: 0 | M9: 0 | N9: =L9*M9 -> 0 | P9: 1.585e-10 | Q9: 0 | R9: 0 | S9: =Q9*R9 -> 0 | U9: 1.585e-10 | V9: 0 | W9: 0 | X9: =V9*W9 -> 0 | Z9: 1.585e-10 | AA9: 0 | AB9: 0 | AC9: =AA9*AB9 -> 0 | AE9: 1.585e-10 | AF9: 0 | AG9: 0 | AH9: =AF9*AG9 -> 0 | AJ9: 1.585e-10 | AK9: 0 | AL9: 0.036464924 | AM9: =AK9*AL9 -> 0 | AO9: 1.585e-10 | AP9: 0 | AQ9: 0.00048120144 | AR9: =AP9*AQ9 -> 0 | AT9: 1.585e-10 | AU9: 0 | AV9: 0 | AW9: =AU9*AV9 -> 0
A10: 2.512e-10 | B10: 0 | C10: 0.19735403 | D10: =B10*C10 -> 0 | F10: 2.512e-10 | G10: 0 | H10: 0 | I10: =G10*H10 -> 0 | K10: 2.512e-10 | L10: 0 | M10: 0 | N10: =L10*M10 -> 0 | P10: 2.512e-10 | Q10: 0 | R10: 0 | S10: =Q10*R10 -> 0 | U10: 2.512e-10 | V10: 0 | W10: 0 | X10: =V10*W10 -> 0 | Z10: 2.512e-10 | AA10: 0 | AB10: 0 | AC10: =AA10*AB10 -> 0 | AE10: 2.512e-10 | AF10: 0 | AG10: 0 | AH10: =AF10*AG10 -> 0 | AJ10: 2.512e-10 | AK10: 0 | AL10: 0.02921837 | AM10: =AK10*AL10 -> 0 | AO10: 2.512e-10 | AP10: 0 | AQ10: 0.0003855744 | AR10: =AP10*AQ10 -> 0 | AT10: 2.512e-10 | AU10: 0 | AV10: 0 | AW10: =AU10*AV10 -> 0
A11: 3.981e-10 | B11: 0 | C11: 0.15842636 | D11: =B11*C11 -> 0 | F11: 3.981e-10 | G11: 0 | H11: 0 | I11: =G11*H11 -> 0 | K11: 3.981e-10 | L11: 0 | M11: 0 | N11: =L11*M11 -> 0 | P11: 3.981e-10 | Q11: 0 | R11: 0 | S11: =Q11*R11 -> 0 | U11: 3.981e-10 | V11: 0 | W11: 0 | X11: =V11*W11 -> 0 | Z11: 3.981e-10 | AA11: 0 | AB11: 0 | AC11: =AA11*AB11 -> 0 | AE11: 3.981e-10 | AF11: 0 | AG11: 0 | AH11: =AF11*AG11 -> 0 | AJ11: 3.981e-10 | AK11: 0 | AL11: 0.023454092 | AM11: =AK11*AL11 -> 0 | AO11: 3.981e-10 | AP11: 0 | AQ11: 0.00030950845 | AR11: =AP11*AQ11 -> 0 | AT11: 3.981e-10 | AU11: 0 | AV11: 0 | AW11: =AU11*AV11 -> 0
A12: 6.31e-10 | B12: 0 | C12: 0.12398901 | D12: =B12*C12 -> 0 | F12: 6.31e-10 | G12: 0 | H12: 0 | I12: =G12*H12 -> 0 | K12: 6.31e-10 | L12: 0 | M12: 0 | N12: =L12*M12 -> 0 | P12: 6.31e-10 | Q12: 0 | R12: 0 | S12: =Q12*R12 -> 0 | U12: 6.31e-10 | V12: 0 | W12: 0 | X12: =V12*W12 -> 0 | Z12: 6.31e-10 | AA12: 0 | AB12: 0 | AC12: =AA12*AB12 -> 0 | AE12: 6.31e-10 | AF12: 0 | AG12: 0 | AH12: =AF12*AG12 -> 0 | AJ12: 6.31e-10 | AK12: 0 | AL12: 0.018354481 | AM12: =AK12*AL12 -> 0 | AO12: 6.31e-10 | AP12: 0 | AQ12: 0.00024221345 | AR12: =AP12*AQ12 -> 0 | AT12: 6.31e-10 | AU12: 0 | AV12: 0 | AW12: =AU12*AV12 -> 0
A13: 1e-09 | B13: 0 | C13: 0.099359413 | D13: =B13*C13 -> 0 | F13: 1e-09 | G13: 0 | H13: 0 | I13: =G13*H13 -> 0 | K13: 1e-09 | L13: 0 | M13: 0 | N13: =L13*M13 -> 0 | P13: 1e-09 | Q13: 0 | R13: 0 | S13: =Q13*R13 -> 0 | U13: 1e-09 | V13: 0 | W13: 0 | X13: =V13*W13 -> 0 | Z13: 1e-09 | AA13: 0 | AB13: 0 | AC13: =AA13*AB13 -> 0 | AE13: 1e-09 | AF13: 0 | AG13: 0 | AH13: =AF13*AG13 -> 0 | AJ13: 1e-09 | AK13: 0 | AL13: 0.014706904 | AM13: =AK13*AL13 -> 0 | AO13: 1e-09 | AP13: 0 | AQ13: 0.00019407987 | AR13: =AP13*AQ13 -> 0 | AT13: 1e-09 | AU13: 0 | AV13: 0 | AW13: =AU13*AV13 -> 0
A14: 1.585e-09 | B14: 165.972 | C14: 0.079770429 | D14: =B14*C14 -> 13.239658 | F14: 1.585e-09 | G14: 165.972 | H14: 0 | I14: =G14*H14 -> 0 | K14: 1.585e-09 | L14: 165.972 | M14: 0 | N14: =L14*M14 -> 0 | P14: 1.585e-09 | Q14: 165.972 | R14: 0 | S14: =Q14*R14 -> 0 | U14: 1.585e-09 | V14: 165.972 | W14: 0 | X14: =V14*W14 -> 0 | Z14: 1.585e-09 | AA14: 165.972 | AB14: 0 | AC14: =AA14*AB14 -> 0 | AE14: 1.585e-09 | AF14: 165.972 | AG14: 0 | AH14: =AF14*AG14 -> 0 | AJ14: 1.585e-09 | AK14: 165.972 | AL14: 0.011805427 | AM14: =AK14*AL14 -> 1.9593704 | AO14: 1.585e-09 | AP14: 165.972 | AQ14: 0.0001557925 | AR14: =AP14*AQ14 -> 0.025857192 | AT14: 1.585e-09 | AU14: 165.972 | AV14: 0 | AW14: =AU14*AV14 -> 0
... A115: 30 | B115: 0 | C115: 1.6672881e-09 | D115: =B115*C115 -> 0 | F115: 30 | G115: 0 | H115: 3.9919942e-05 | I115: =G115*H115 -> 0 | K115: 30 | L115: 0 | M115: 0 | N115: =L115*M115 -> 0 | P115: 30 | Q115: 0 | R115: 0 | S115: =Q115*R115 -> 0 | U115: 30 | V115: 0 | W115: 1.2760579e-06 | X115: =V115*W115 -> 0 | Z115: 30 | AA115: 0 | AB115: 0 | AC115: =AA115*AB115 -> 0 | AE115: 30 | AF115: 0 | AG115: 0 | AH115: =AF115*AG115 -> 0 | AJ115: 30 | AK115: 0 | AL115: 0 | AM115: =AK115*AL115 -> 0 | AO115: 30 | AP115: 0 | AQ115: 0 | AR115: =AP115*AQ115 -> 0 | AT115: 30 | AU115: 0 | AV115: 0 | AW115: =AU115*AV115 -> 0
A117: sum | D117: =SUM(D3:D116) -> 104907.71 | I117: =SUM(I3:I116) -> 15.950787 | N117: =SUM(N3:N116) -> 39.958464 | S117: =SUM(S3:S116) -> 21.813131 | X117: =SUM(X3:X116) -> 4.5855611 | AC117: =SUM(AC3:AC116) -> 0.16542079 | AH117: =SUM(AH3:AH116) -> 4.6662476 | AM117: =SUM(AM3:AM116) -> 510.9682 | AR117: =SUM(AR3:AR116) -> 8.5851755 | AW117: =SUM(AW3:AW116) -> 25.607208
A124: activity error | B124: =ABS((D117-activity_Ami!D242)/activity_Ami!D242) -> 2.1006009 | F124: activity error | G124: =ABS((I117-activity_Ami!I242)/activity_Ami!I242) -> 0.07972859 | K124: activity error | L124: =ABS((N117-activity_Ami!N242)/activity_Ami!N242) -> 0.14432493 | P124: activity error | Q124: =ABS((S117-activity_Ami!S242)/activity_Ami!S242) -> 0.049941699 | U124: activity error | V124: =ABS((X117-activity_Ami!X242)/activity_Ami!X242) -> 0.11985551 | Z124: activity error | AA124: =ABS((AC117-activity_Ami!AC242)/activity_Ami!AC242) -> 0.097225605 | AE124: activity error | AF124: =ABS((AH117-activity_Ami!AH242)/activity_Ami!AH242) -> 0.069652511 | AJ124: activity error | AK124: =ABS((AM117-activity_Ami!AM242)/activity_Ami!AM242) -> 0.2835092 | AO124: activity error | AP124: =ABS((AR117-activity_Ami!AR242)/activity_Ami!AR242) -> 0.18144838 | AT124: activity error | AU124: =ABS((AW117-activity_Ami!AW242)/activity_Ami!AW242) -> 0.13372311
A130: ri | B130: =activity_Ami!D242/D117 -> 0.32251813 | F130: ri | G130: =activity_Ami!I242/I117 -> 0.92615867 | K130: ri | L130: =activity_Ami!N242/N117 -> 0.87387767 | P130: ri | Q130: =activity_Ami!S242/S117 -> 0.95243384 | U130: ri | V130: =activity_Ami!X242/X117 -> 0.89297234 | Z130: ri | AA130: =activity_Ami!AC242/AC117 -> 0.91138959 | AE130: ri | AF130: =activity_Ami!AH242/AH117 -> 0.93488305 | AJ130: ri | AK130: =activity_Ami!AM242/AM117 -> 1.3956913 | AO130: ri | AP130: =activity_Ami!AR242/AR117 -> 1.2216701 | AT130: ri | AU130: =activity_Ami!AW242/AW117 -> 0.88204959
A137: ERRE | B137: =0.1*(B124+G124+L124+Q124+V124+AA124+AF124+AK124+AP124+AU124) -> 0.32600105
A144: DEV | B144: =(((B130-1)^2+(G130-1)^2+(L130-1)^2+(Q130-1)^2+(V130-1)^2+(AA130-1)^2+(AF130-1)^2+(AK130-1)^2+(AP130-1)^2+(AU130-1)^2)/9)^0.5 -> 0.2839742

Sheet 113groups_result
A1: Au-197 | F1: Fe-56 | K1: Al-27 | P1: Ni-58 | U1: Fe-54 | Z1: Cu-63 | AE1: Ti-48 | AJ1: Na-23 | AO1: Co-59 | AT1: S-32
A2: Energy | B2: Flux | C2: Coefficient | D2: Activity | F2: Energy | G2: Flux | H2: Coefficient | I2: Activity | K2: Energy | L2: Flux | M2: Coefficient | N2: Activity | P2: Energy | Q2: Flux | R2: Coefficient | S2: Activity | U2: Energy | V2: Flux | W2: Coefficient | X2: Activity | Z2: Energy | AA2: Flux | AB2: Coefficient | AC2: Activity | AE2: Energy | AF2: Flux | AG2: Coefficient | AH2: Activity | AJ2: Energy | AK2: Flux | AL2: Coefficient | AM2: Activity | AO2: Energy | AP2: Flux | AQ2: Coefficient | AR2: Activity | AT2: Energy | AU2: Flux | AV2: Coefficient | AW2: Activity
A3: 1e-11 | B3: 0 | C3: 0 | D3: =B3*C3 -> 0 | F3: 1e-11 | G3: 0 | H3: 0 | I3: =G3*H3 -> 0 | K3: 1e-11 | L3: 0 | M3: 0 | N3: =L3*M3 -> 0 | P3: 1e-11 | Q3: 0 | R3: 0 | S3: =Q3*R3 -> 0 | U3: 1e-11 | V3: 0 | W3: 0 | X3: =V3*W3 -> 0 | Z3: 1e-11 | AA3: 0 | AB3: 0 | AC3: =AA3*AB3 -> 0 | AE3: 1e-11 | AF3: 0 | AG3: 0 | AH3: =AF3*AG3 -> 0 | AJ3: 1e-11 | AK3: 0 | AL3: 0 | AM3: =AK3*AL3 -> 0 | AO3: 1e-11 | AP3: 0 | AQ3: 0 | AR3: =AP3*AQ3 -> 0 | AT3: 1e-11 | AU3: 0 | AV3: 0 | AW3: =AU3*AV3 -> 0
A4: 1.585e-11 | B4: 0 | C4: 0.79894358 | D4: =B4*C4 -> 0 | F4: 1.585e-11 | G4: 0 | H4: 0 | I4: =G4*H4 -> 0 | K4: 1.585e-11 | L4: 0 | M4: 0 | N4: =L4*M4 -> 0 | P4: 1.585e-11 | Q4: 0 | R4: 0 | S4: =Q4*R4 -> 0 | U4: 1.585e-11 | V4: 0 | W4: 0 | X4: =V4*W4 -> 0 | Z4: 1.585e-11 | AA4: 0 | AB4: 0 | AC4: =AA4*AB4 -> 0 | AE4: 1.585e-11 | AF4: 0 | AG4: 0 | AH4: =AF4*AG4 -> 0 | AJ4: 1.585e-11 | AK4: 0 | AL4: 0.11829256 | AM4: =AK4*AL4 -> 0 | AO4: 1.585e-11 | AP4: 0 | AQ4: 0.0015610146 | AR4: =AP4*AQ4 -> 0 | AT4: 1.585e-11 | AU4: 0 | AV4: 0 | AW4: =AU4*AV4 -> 0
A5: 2.512e-11 | B5: 0 | C5: 0.62523349 | D5: =B5*C5 -> 0 | F5: 2.512e-11 | G5: 0 | H5: 0 | I5: =G5*H5 -> 0 | K5: 2.512e-11 | L5: 0 | M5: 0 | N5: =L5*M5 -> 0 | P5: 2.512e-11 | Q5: 0 | R5: 0 | S5: =Q5*R5 -> 0 | U5: 2.512e-11 | V5: 0 | W5: 0 | X5: =V5*W5 -> 0 | Z5: 2.512e-11 | AA5: 0 | AB5: 0 | AC5: =AA5*AB5 -> 0 | AE5: 2.512e-11 | AF5: 0 | AG5: 0 | AH5: =AF5*AG5 -> 0 | AJ5: 2.512e-11 | AK5: 0 | AL5: 0.092572442 | AM5: =AK5*AL5 -> 0 | AO5: 2.512e-11 | AP5: 0 | AQ5: 0.0012216071 | AR5: =AP5*AQ5 -> 0 | AT5: 2.512e-11 | AU5: 0 | AV5: 0 | AW5: =AU5*AV5 -> 0
A6: 3.981e-11 | B6: 0 | C6: 0.48929277 | D6: =B6*C6 -> 0 | F6: 3.981e-11 | G6: 0 | H6: 0 | I6: =G6*H6 -> 0 | K6: 3.981e-11 | L6: 0 | M6: 0 | N6: =L6*M6 -> 0 | P6: 3.981e-11 | Q6: 0 | R6: 0 | S6: =Q6*R6 -> 0 | U6: 3.981e-11 | V6: 0 | W6: 0 | X6: =V6*W6 -> 0 | Z6: 3.981e-11 | AA6: 0 | AB6: 0 | AC6: =AA6*AB6 -> 0 | AE6: 3.981e-11 | AF6: 0 | AG6: 0 | AH6: =AF6*AG6 -> 0 | AJ6: 3.981e-11 | AK6: 0 | AL6: 0.072444631 | AM6: =AK6*AL6 -> 0 | AO6: 3.981e-11 | AP6: 0 | AQ6: 0.00095599865 | AR6: =AP6*AQ6 -> 0 | AT6: 3.981e-11 | AU6: 0 | AV6: 0 | AW6: =AU6*AV6 -> 0
A7: 6.31e-11 | B7: 0 | C7: 0.39206037 | D7: =B7*C7 -> 0 | F7: 6.31e-11 | G7: 0 | H7: 0 | I7: =G7*H7 -> 0 | K7: 6.31e-11 | L7: 0 | M7: 0 | N7: =L7*M7 -> 0 | P7: 6.31e-11 | Q7: 0 | R7: 0 | S7: =Q7*R7 -> 0 | U7: 6.31e-11 | V7: 0 | W7: 0 | X7: =V7*W7 -> 0 | Z7: 6.31e-11 | AA7: 0 | AB7: 0 | AC7: =AA7*AB7 -> 0 | AE7: 6.31e-11 | AF7: 0 | AG7: 0 | AH7: =AF7*AG7 -> 0 | AJ7: 6.31e-11 | AK7: 0 | AL7: 0.058047995 | AM7: =AK7*AL7 -> 0 | AO7: 6.31e-11 | AP7: 0 | AQ7: 0.00076601604 | AR7: =AP7*AQ7 -> 0 | AT7: 6.31e-11 | AU7: 0 | AV7: 0 | AW7: =AU7*AV7 -> 0
A8: 1e-10 | B8: 0 | C8: 0.31471774 | D8: =B8*C8 -> 0 | F8: 1e-10 | G8: 0 | H8: 0 | I8: =G8*H8 -> 0 | K8: 1e-10 | L8: 0 | M8: 0 | N8: =L8*M8 -> 0 | P8: 1e-10 | Q8: 0 | R8: 0 | S8: =Q8*R8 -> 0 | U8: 1e-10 | V8: 0 | W8: 0 | X8: =V8*W8 -> 0 | Z8: 1e-10 | AA8: 0 | AB8: 0 | AC8: =AA8*AB8 -> 0 | AE8: 1e-10 | AF8: 0 | AG8: 0 | AH8: =AF8*AG8 -> 0 | AJ8: 1e-10 | AK8: 0 | AL8: 0.046596237 | AM8: =AK8*AL8 -> 0 | AO8: 1e-10 | AP8: 0 | AQ8: 0.00061489599 | AR8: =AP8*AQ8 -> 0 | AT8: 1e-10 | AU8: 0 | AV8: 0 | AW8: =AU8*AV8 -> 0
A9: 1.585e-10 | B9: 0 | C9: 0.24629436 | D9: =B9*C9 -> 0 | F9: 1.585e-10 | G9: 0 | H9: 0 | I9: =G9*H9 -> 0 | K9: 1.585e-10 | L9: 0 | M9: 0 | N9: =L9*M9 -> 0 | P9: 1.585e-10 | Q9: 0 | R9: 0 | S9: =Q9*R9 -> 0 | U9: 1.585e-10 | V9: 0 | W9: 0 | X9: =V9*W9 -> 0 | Z9: 1.585e-10 | AA9: 0 | AB9: 0 | AC9: =AA9*AB9 -> 0 | AE9: 1.585e-10 | AF9: 0 | AG9: 0 | AH9: =AF9*AG9 -> 0 | AJ9: 1.585e-10 | AK9: 0 | AL9: 0.036464924 | AM9: =AK9*AL9 -> 0 | AO9: 1.585e-10 | AP9: 0 | AQ9: 0.00048120144 | AR9: =AP9*AQ9 -> 0 | AT9: 1.585e-10 | AU9: 0 | AV9: 0 | AW9: =AU9*AV9 -> 0
A10: 2.512e-10 | B10: 0 | C10: 0.19735403 | D10: =B10*C10 -> 0 | F10: 2.512e-10 | G10: 0 | H10: 0 | I10: =G10*H10 -> 0 | K10: 2.512e-10 | L10: 0 | M10: 0 | N10: =L10*M10 -> 0 | P10: 2.512e-10 | Q10: 0 | R10: 0 | S10: =Q10*R10 -> 0 | U10: 2.512e-10 | V10: 0 | W10: 0 | X10: =V10*W10 -> 0 | Z10: 2.512e-10 | AA10: 0 | AB10: 0 | AC10: =AA10*AB10 -> 0 | AE10: 2.512e-10 | AF10: 0 | AG10: 0 | AH10: =AF10*AG10 -> 0 | AJ10: 2.512e-10 | AK10: 0 | AL10: 0.02921837 | AM10: =AK10*AL10 -> 0 | AO10: 2.512e-10 | AP10: 0 | AQ10: 0.0003855744 | AR10: =AP10*AQ10 -> 0 | AT10: 2.512e-10 | AU10: 0 | AV10: 0 | AW10: =AU10*AV10 -> 0
A11: 3.981e-10 | B11: 0 | C11: 0.15842636 | D11: =B11*C11 -> 0 | F11: 3.981e-10 | G11: 0 | H11: 0 | I11: =G11*H11 -> 0 | K11: 3.981e-10 | L11: 0 | M11: 0 | N11: =L11*M11 -> 0 | P11: 3.981e-10 | Q11: 0 | R11: 0 | S11: =Q11*R11 -> 0 | U11: 3.981e-10 | V11: 0 | W11: 0 | X11: =V11*W11 -> 0 | Z11: 3.981e-10 | AA11: 0 | AB11: 0 | AC11: =AA11*AB11 -> 0 | AE11: 3.981e-10 | AF11: 0 | AG11: 0 | AH11: =AF11*AG11 -> 0 | AJ11: 3.981e-10 | AK11: 0 | AL11: 0.023454092 | AM11: =AK11*AL11 -> 0 | AO11: 3.981e-10 | AP11: 0 | AQ11: 0.00030950845 | AR11: =AP11*AQ11 -> 0 | AT11: 3.981e-10 | AU11: 0 | AV11: 0 | AW11: =AU11*AV11 -> 0
A12: 6.31e-10 | B12: 0 | C12: 0.12398901 | D12: =B12*C12 -> 0 | F12: 6.31e-10 | G12: 0 | H12: 0 | I12: =G12*H12 -> 0 | K12: 6.31e-10 | L12: 0 | M12: 0 | N12: =L12*M12 -> 0 | P12: 6.31e-10 | Q12: 0 | R12: 0 | S12: =Q12*R12 -> 0 | U12: 6.31e-10 | V12: 0 | W12: 0 | X12: =V12*W12 -> 0 | Z12: 6.31e-10 | AA12: 0 | AB12: 0 | AC12: =AA12*AB12 -> 0 | AE12: 6.31e-10 | AF12: 0 | AG12: 0 | AH12: =AF12*AG12 -> 0 | AJ12: 6.31e-10 | AK12: 0 | AL12: 0.018354481 | AM12: =AK12*AL12 -> 0 | AO12: 6.31e-10 | AP12: 0 | AQ12: 0.00024221345 | AR12: =AP12*AQ12 -> 0 | AT12: 6.31e-10 | AU12: 0 | AV12: 0 | AW12: =AU12*AV12 -> 0
A13: 1e-09 | B13: 0 | C13: 0.099359413 | D13: =B13*C13 -> 0 | F13: 1e-09 | G13: 0 | H13: 0 | I13: =G13*H13 -> 0 | K13: 1e-09 | L13: 0 | M13: 0 | N13: =L13*M13 -> 0 | P13: 1e-09 | Q13: 0 | R13: 0 | S13: =Q13*R13 -> 0 | U13: 1e-09 | V13: 0 | W13: 0 | X13: =V13*W13 -> 0 | Z13: 1e-09 | AA13: 0 | AB13: 0 | AC13: =AA13*AB13 -> 0 | AE13: 1e-09 | AF13: 0 | AG13: 0 | AH13: =AF13*AG13 -> 0 | AJ13: 1e-09 | AK13: 0 | AL13: 0.014706904 | AM13: =AK13*AL13 -> 0 | AO13: 1e-09 | AP13: 0 | AQ13: 0.00019407987 | AR13: =AP13*AQ13 -> 0 | AT13: 1e-09 | AU13: 0 | AV13: 0 | AW13: =AU13*AV13 -> 0
A14: 1.585e-09 | B14: 11024.769 | C14: 0.079770429 | D14: =B14*C14 -> 879.45052 | F14: 1.585e-09 | G14: 11024.769 | H14: 0 | I14: =G14*H14 -> 0 | K14: 1.585e-09 | L14: 11024.769 | M14: 0 | N14: =L14*M14 -> 0 | P14: 1.585e-09 | Q14: 11024.769 | R14: 0 | S14: =Q14*R14 -> 0 | U14: 1.585e-09 | V14: 11024.769 | W14: 0 | X14: =V14*W14 -> 0 | Z14: 1.585e-09 | AA14: 11024.769 | AB14: 0 | AC14: =AA14*AB14 -> 0 | AE14: 1.585e-09 | AF14: 11024.769 | AG14: 0 | AH14: =AF14*AG14 -> 0 | AJ14: 1.585e-09 | AK14: 11024.769 | AL14: 0.011805427 | AM14: =AK14*AL14 -> 130.1521 | AO14: 1.585e-09 | AP14: 11024.769 | AQ14: 0.0001557925 | AR14: =AP14*AQ14 -> 1.7175762 | AT14: 1.585e-09 | AU14: 11024.769 | AV14: 0 | AW14: =AU14*AV14 -> 0
... A115: 30 | B115: 0 | C115: 1.6672881e-09 | D115: =B115*C115 -> 0 | F115: 30 | G115: 0 | H115: 3.9919942e-05 | I115: =G115*H115 -> 0 | K115: 30 | L115: 0 | M115: 0 | N115: =L115*M115 -> 0 | P115: 30 | Q115: 0 | R115: 0 | S115: =Q115*R115 -> 0 | U115: 30 | V115: 0 | W115: 1.2760579e-06 | X115: =V115*W115 -> 0 | Z115: 30 | AA115: 0 | AB115: 0 | AC115: =AA115*AB115 -> 0 | AE115: 30 | AF115: 0 | AG115: 0 | AH115: =AF115*AG115 -> 0 | AJ115: 30 | AK115: 0 | AL115: 0 | AM115: =AK115*AL115 -> 0 | AO115: 30 | AP115: 0 | AQ115: 0 | AR115: =AP115*AQ115 -> 0 | AT115: 30 | AU115: 0 | AV115: 0 | AW115: =AU115*AV115 -> 0
A117: sum | D117: =SUM(D3:D116) -> 33834.692 | I117: =SUM(I3:I116) -> 12.990988 | N117: =SUM(N3:N116) -> 32.551494 | S117: =SUM(S3:S116) -> 17.712547 | X117: =SUM(X3:X116) -> 3.7236579 | AC117: =SUM(AC3:AC116) -> 0.13467709 | AH117: =SUM(AH3:AH116) -> 3.8065901 | AM117: =SUM(AM3:AM116) -> 700.69933 | AR117: =SUM(AR3:AR116) -> 10.627324 | AW117: =SUM(AW3:AW116) -> 20.793079
A124: activity error | B124: =ABS((D117-activity_Ami!D242)/activity_Ami!D242) -> 1.6152175e-06 | F124: activity error | G124: =ABS((I117-activity_Ami!I242)/activity_Ami!I242) -> 0.12062387 | K124: activity error | L124: =ABS((N117-activity_Ami!N242)/activity_Ami!N242) -> 0.067794862 | P124: activity error | Q124: =ABS((S117-activity_Ami!S242)/activity_Ami!S242) -> 0.14743363 | U124: activity error | V124: =ABS((X117-activity_Ami!X242)/activity_Ami!X242) -> 0.090632824 | Z124: activity error | AA124: =ABS((AC117-activity_Ami!AC242)/activity_Ami!AC242) -> 0.10669543 | AE124: activity error | AF124: =ABS((AH117-activity_Ami!AH242)/activity_Ami!AH242) -> 0.12740836 | AJ124: activity error | AK124: =ABS((AM117-activity_Ami!AM242)/activity_Ami!AM242) -> 0.017464044 | AO124: activity error | AP124: =ABS((AR117-activity_Ami!AR242)/activity_Ami!AR242) -> 0.013259797 | AT124: activity error | AU124: =ABS((AW117-activity_Ami!AW242)/activity_Ami!AW242) -> 0.079415706
A130: ri | B130: =activity_Ami!D242/'113groups_result'!D117 -> 0.99999838 | F130: ri | G130: =activity_Ami!I242/'113groups_result'!I117 -> 1.1371698 | K130: ri | L130: =activity_Ami!N242/'113groups_result'!N117 -> 1.0727253 | P130: ri | Q130: =activity_Ami!S242/'113groups_result'!S117 -> 1.1729292 | U130: ri | V130: =activity_Ami!X242/'113groups_result'!X117 -> 1.0996658 | Z130: ri | AA130: =activity_Ami!AC242/'113groups_result'!AC117 -> 1.119439 | AE130: ri | AF130: =activity_Ami!AH242/'113groups_result'!AH117 -> 1.1460114 | AJ130: ri | AK130: =activity_Ami!AM242/'113groups_result'!AM117 -> 1.0177745 | AO130: ri | AP130: =activity_Ami!AR242/'113groups_result'!AR117 -> 0.98691372 | AT130: ri | AU130: =activity_Ami!AW242/'113groups_result'!AW117 -> 1.0862666
A136: ERRE | B136: =0.1*(B124+G124+L124+Q124+V124+AA124+AF124+AK124+AP124+AU124) -> 0.077073014
A144: DEV | B144: =(((B130-1)^2+(G130-1)^2+(L130-1)^2+(Q130-1)^2+(V130-1)^2+(AA130-1)^2+(AF130-1)^2+(AK130-1)^2+(AP130-1)^2+(AU130-1)^2)/9)^0.5 -> 0.1092685

Sheet 240groups_prior
A1: Au-197 | F1: Fe-56 | K1: Al-27 | P1: Ni-58 | U1: Fe-54 | Z1: Cu-63 | AE1: Ti-48 | AJ1: Na-23 | AO1: Co-59 | AT1: S-32
A2: Energy | B2: Flux | C2: Coefficient | D2: Activity | F2: Energy | G2: Flux | H2: Coefficient | I2: Activity | K2: Energy | L2: Flux | M2: Coefficient | N2: Activity | P2: Energy | Q2: Flux | R2: Coefficient | S2: Activity | U2: Energy | V2: Flux | W2: Coefficient | X2: Activity | Z2: Energy | AA2: Flux | AB2: Coefficient | AC2: Activity | AE2: Energy | AF2: Flux | AG2: Coefficient | AH2: Activity | AJ2: Energy | AK2: Flux | AL2: Coefficient | AM2: Activity | AO2: Energy | AP2: Flux | AQ2: Coefficient | AR2: Activity | AT2: Energy | AU2: Flux | AV2: Coefficient | AW2: Activity
A3: 1e-11 | B3: 0 | C3: 0 | D3: =B3*C3 -> 0 | F3: 1e-11 | G3: 0 | H3: 0 | I3: =G3*H3 -> 0 | K3: 1e-11 | L3: 0 | M3: 0 | N3: =L3*M3 -> 0 | P3: 1e-11 | Q3: 0 | R3: 0 | S3: =Q3*R3 -> 0 | U3: 1e-11 | V3: 0 | W3: 0 | X3: =V3*W3 -> 0 | Z3: 1e-11 | AA3: 0 | AB3: 0 | AC3: =AA3*AB3 -> 0 | AE3: 1e-11 | AF3: 0 | AG3: 0 | AH3: =AF3*AG3 -> 0 | AJ3: 1e-11 | AK3: 0 | AL3: 0 | AM3: =AK3*AL3 -> 0 | AO3: 1e-11 | AP3: 0 | AQ3: 0 | AR3: =AP3*AQ3 -> 0 | AT3: 1e-11 | AU3: 0 | AV3: 0 | AW3: =AU3*AV3 -> 0
A4: 1.1286e-11 | B4: 0 | C4: 0.8581143 | D4: =B4*C4 -> 0 | F4: 1.1286e-11 | G4: 0 | H4: 0 | I4: =G4*H4 -> 0 | K4: 1.1286e-11 | L4: 0 | M4: 0 | N4: =L4*M4 -> 0 | P4: 1.1286e-11 | Q4: 0 | R4: 0 | S4: =Q4*R4 -> 0 | U4: 1.1286e-11 | V4: 0 | W4: 0 | X4: =V4*W4 -> 0 | Z4: 1.1286e-11 | AA4: 0 | AB4: 0 | AC4: =AA4*AB4 -> 0 | AE4: 1.1286e-11 | AF4: 0 | AG4: 0 | AH4: =AF4*AG4 -> 0 | AJ4: 1.1286e-11 | AK4: 0 | AL4: 0.12705359 | AM4: =AK4*AL4 -> 0 | AO4: 1.1286e-11 | AP4: 0 | AQ4: 0.0016766268 | AR4: =AP4*AQ4 -> 0 | AT4: 1.1286e-11 | AU4: 0 | AV4: 0 | AW4: =AU4*AV4 -> 0
A5: 1.2738e-11 | B5: 0 | C5: 0.79702672 | D5: =B5*C5 -> 0 | F5: 1.2738e-11 | G5: 0 | H5: 0 | I5: =G5*H5 -> 0 | K5: 1.2738e-11 | L5: 0 | M5: 0 | N5: =L5*M5 -> 0 | P5: 1.2738e-11 | Q5: 0 | R5: 0 | S5: =Q5*R5 -> 0 | U5: 1.2738e-11 | V5: 0 | W5: 0 | X5: =V5*W5 -> 0 | Z5: 1.2738e-11 | AA5: 0 | AB5: 0 | AC5: =AA5*AB5 -> 0 | AE5: 1.2738e-11 | AF5: 0 | AG5: 0 | AH5: =AF5*AG5 -> 0 | AJ5: 1.2738e-11 | AK5: 0 | AL5: 0.1180086 | AM5: =AK5*AL5 -> 0 | AO5: 1.2738e-11 | AP5: 0 | AQ5: 0.0015572688 | AR5: =AP5*AQ5 -> 0 | AT5: 1.2738e-11 | AU5: 0 | AV5: 0 | AW5: =AU5*AV5 -> 0
A6: 1.4376e-11 | B6: 0 | C6: 0.75888799 | D6: =B6*C6 -> 0 | F6: 1.4376e-11 | G6: 0 | H6: 0 | I6: =G6*H6 -> 0 | K6: 1.4376e-11 | L6: 0 | M6: 0 | N6: =L6*M6 -> 0 | P6: 1.4376e-11 | Q6: 0 | R6: 0 | S6: =Q6*R6 -> 0 | U6: 1.4376e-11 | V6: 0 | W6: 0 | X6: =V6*W6 -> 0 | Z6: 1.4376e-11 | AA6: 0 | AB6: 0 | AC6: =AA6*AB6 -> 0 | AE6: 1.4376e-11 | AF6: 0 | AG6: 0 | AH6: =AF6*AG6 -> 0 | AJ6: 1.4376e-11 | AK6: 0 | AL6: 0.11236169 | AM6: =AK6*AL6 -> 0 | AO6: 1.4376e-11 | AP6: 0 | AQ6: 0.0014827482 | AR6: =AP6*AQ6 -> 0 | AT6: 1.4376e-11 | AU6: 0 | AV6: 0 | AW6: =AU6*AV6 -> 0
A7: 1.6225e-11 | B7: 0 | C7: 0.72257458 | D7: =B7*C7 -> 0 | F7: 1.6225e-11 | G7: 0 | H7: 0 | I7: =G7*H7 -> 0 | K7: 1.6225e-11 | L7: 0 | M7: 0 | N7: =L7*M7 -> 0 | P7: 1.6225e-11 | Q7: 0 | R7: 0 | S7: =Q7*R7 -> 0 | U7: 1.6225e-11 | V7: 0 | W7: 0 | X7: =V7*W7 -> 0 | Z7: 1.6225e-11 | AA7: 0 | AB7: 0 | AC7: =AA7*AB7 -> 0 | AE7: 1.6225e-11 | AF7: 0 | AG7: 0 | AH7: =AF7*AG7 -> 0 | AJ7: 1.6225e-11 | AK7: 0 | AL7: 0.10698532 | AM7: =AK7*AL7 -> 0 | AO7: 1.6225e-11 | AP7: 0 | AQ7: 0.0014118024 | AR7: =AP7*AQ7 -> 0 | AT7: 1.6225e-11 | AU7: 0 | AV7: 0 | AW7: =AU7*AV7 -> 0
A8: 1.8313e-11 | B8: 0 | C8: 0.6715388 | D8: =B8*C8 -> 0 | F8: 1.8313e-11 | G8: 0 | H8: 0 | I8: =G8*H8 -> 0 | K8: 1.8313e-11 | L8: 0 | M8: 0 | N8: =L8*M8 -> 0 | P8: 1.8313e-11 | Q8: 0 | R8: 0 | S8: =Q8*R8 -> 0 | U8: 1.8313e-11 | V8: 0 | W8: 0 | X8: =V8*W8 -> 0 | Z8: 1.8313e-11 | AA8: 0 | AB8: 0 | AC8: =AA8*AB8 -> 0 | AE8: 1.8313e-11 | AF8: 0 | AG8: 0 | AH8: =AF8*AG8 -> 0 | AJ8: 1.8313e-11 | AK8: 0 | AL8: 0.099428513 | AM8: =AK8*AL8 -> 0 | AO8: 1.8313e-11 | AP8: 0 | AQ8: 0.0013120832 | AR8: =AP8*AQ8 -> 0 | AT8: 1.8313e-11 | AU8: 0 | AV8: 0 | AW8: =AU8*AV8 -> 0
A9: 2.0668e-11 | B9: 0 | C9: 0.62373354 | D9: =B9*C9 -> 0 | F9: 2.0668e-11 | G9: 0 | H9: 0 | I9: =G9*H9 -> 0 | K9: 2.0668e-11 | L9: 0 | M9: 0 | N9: =L9*M9 -> 0 | P9: 2.0668e-11 | Q9: 0 | R9: 0 | S9: =Q9*R9 -> 0 | U9: 2.0668e-11 | V9: 0 | W9: 0 | X9: =V9*W9 -> 0 | Z9: 2.0668e-11 | AA9: 0 | AB9: 0 | AC9: =AA9*AB9 -> 0 | AE9: 2.0668e-11 | AF9: 0 | AG9: 0 | AH9: =AF9*AG9 -> 0 | AJ9: 2.0668e-11 | AK9: 0 | AL9: 0.092350036 | AM9: =AK9*AL9 -> 0 | AO9: 2.0668e-11 | AP9: 0 | AQ9: 0.0012186774 | AR9: =AP9*AQ9 -> 0 | AT9: 2.0668e-11 | AU9: 0 | AV9: 0 | AW9: =AU9*AV9 -> 0
A10: 2.3326e-11 | B10: 0 | C10: 0.59388654 | D10: =B10*C10 -> 0 | F10: 2.3326e-11 | G10: 0 | H10: 0 | I10: =G10*H10 -> 0 | K10: 2.3326e-11 | L10: 0 | M10: 0 | N10: =L10*M10 -> 0 | P10: 2.3326e-11 | Q10: 0 | R10: 0 | S10: =Q10*R10 -> 0 | U10: 2.3326e-11 | V10: 0 | W10: 0 | X10: =V10*W10 -> 0 | Z10: 2.3326e-11 | AA10: 0 | AB10: 0 | AC10: =AA10*AB10 -> 0 | AE10: 2.3326e-11 | AF10: 0 | AG10: 0 | AH10: =AF10*AG10 -> 0 | AJ10: 2.3326e-11 | AK10: 0 | AL10: 0.087931317 | AM10: =AK10*AL10 -> 0 | AO10: 2.3326e-11 | AP10: 0 | AQ10: 0.0011603585 | AR10: =AP10*AQ10 -> 0 | AT10: 2.3326e-11 | AU10: 0 | AV10: 0 | AW10: =AU10*AV10 -> 0
A11: 2.6327e-11 | B11: 0 | C11: 0.56546976 | D11: =B11*C11 -> 0 | F11: 2.6327e-11 | G11: 0 | H11: 0 | I11: =G11*H11 -> 0 | K11: 2.6327e-11 | L11: 0 | M11: 0 | N11: =L11*M11 -> 0 | P11: 2.6327e-11 | Q11: 0 | R11: 0 | S11: =Q11*R11 -> 0 | U11: 2.6327e-11 | V11: 0 | W11: 0 | X11: =V11*W11 -> 0 | Z11: 2.6327e-11 | AA11: 0 | AB11: 0 | AC11: =AA11*AB11 -> 0 | AE11: 2.6327e-11 | AF11: 0 | AG11: 0 | AH11: =AF11*AG11 -> 0 | AJ11: 2.6327e-11 | AK11: 0 | AL11: 0.083723831 | AM11: =AK11*AL11 -> 0 | AO11: 2.6327e-11 | AP11: 0 | AQ11: 0.0011048333 | AR11: =AP11*AQ11 -> 0 | AT11: 2.6327e-11 | AU11: 0 | AV11: 0 | AW11: =AU11*AV11 -> 0
